{
  "nbformat": 4,
  "nbformat_minor": 0,
  "metadata": {
    "colab": {
      "provenance": [],
      "include_colab_link": true
    },
    "kernelspec": {
      "name": "python3",
      "display_name": "Python 3"
    },
    "language_info": {
      "name": "python"
    }
  },
  "cells": [
    {
      "cell_type": "markdown",
      "metadata": {
        "id": "view-in-github",
        "colab_type": "text"
      },
      "source": [
        "<a href=\"https://colab.research.google.com/github/martinjamouss/ML-Lab/blob/main/Assignment7.ipynb\" target=\"_parent\"><img src=\"https://colab.research.google.com/assets/colab-badge.svg\" alt=\"Open In Colab\"/></a>"
      ]
    },
    {
      "cell_type": "markdown",
      "source": [
        "# 1.) Import an asset price from Yahoo Finance"
      ],
      "metadata": {
        "id": "6dJuZDx9qWeM"
      }
    },
    {
      "cell_type": "code",
      "source": [
        "pip install yfinance"
      ],
      "metadata": {
        "colab": {
          "base_uri": "https://localhost:8080/"
        },
        "id": "2iuH-hGKz6Us",
        "outputId": "007c4239-4b31-4459-db60-b95db3f54390"
      },
      "execution_count": 1,
      "outputs": [
        {
          "output_type": "stream",
          "name": "stdout",
          "text": [
            "Looking in indexes: https://pypi.org/simple, https://us-python.pkg.dev/colab-wheels/public/simple/\n",
            "Collecting yfinance\n",
            "  Downloading yfinance-0.2.12-py2.py3-none-any.whl (59 kB)\n",
            "\u001b[2K     \u001b[90m━━━━━━━━━━━━━━━━━━━━━━━━━━━━━━━━━━━━━━━━\u001b[0m \u001b[32m59.2/59.2 KB\u001b[0m \u001b[31m1.5 MB/s\u001b[0m eta \u001b[36m0:00:00\u001b[0m\n",
            "\u001b[?25hCollecting requests>=2.26\n",
            "  Downloading requests-2.28.2-py3-none-any.whl (62 kB)\n",
            "\u001b[2K     \u001b[90m━━━━━━━━━━━━━━━━━━━━━━━━━━━━━━━━━━━━━━━━\u001b[0m \u001b[32m62.8/62.8 KB\u001b[0m \u001b[31m3.8 MB/s\u001b[0m eta \u001b[36m0:00:00\u001b[0m\n",
            "\u001b[?25hCollecting frozendict>=2.3.4\n",
            "  Downloading frozendict-2.3.5-cp38-cp38-manylinux_2_17_x86_64.manylinux2014_x86_64.whl (111 kB)\n",
            "\u001b[2K     \u001b[90m━━━━━━━━━━━━━━━━━━━━━━━━━━━━━━━━━━━━━━━\u001b[0m \u001b[32m111.2/111.2 KB\u001b[0m \u001b[31m7.1 MB/s\u001b[0m eta \u001b[36m0:00:00\u001b[0m\n",
            "\u001b[?25hCollecting beautifulsoup4>=4.11.1\n",
            "  Downloading beautifulsoup4-4.11.2-py3-none-any.whl (129 kB)\n",
            "\u001b[2K     \u001b[90m━━━━━━━━━━━━━━━━━━━━━━━━━━━━━━━━━━━━━━━\u001b[0m \u001b[32m129.4/129.4 KB\u001b[0m \u001b[31m8.0 MB/s\u001b[0m eta \u001b[36m0:00:00\u001b[0m\n",
            "\u001b[?25hRequirement already satisfied: numpy>=1.16.5 in /usr/local/lib/python3.8/dist-packages (from yfinance) (1.22.4)\n",
            "Requirement already satisfied: pytz>=2022.5 in /usr/local/lib/python3.8/dist-packages (from yfinance) (2022.7.1)\n",
            "Collecting html5lib>=1.1\n",
            "  Downloading html5lib-1.1-py2.py3-none-any.whl (112 kB)\n",
            "\u001b[2K     \u001b[90m━━━━━━━━━━━━━━━━━━━━━━━━━━━━━━━━━━━━━━━\u001b[0m \u001b[32m112.2/112.2 KB\u001b[0m \u001b[31m9.4 MB/s\u001b[0m eta \u001b[36m0:00:00\u001b[0m\n",
            "\u001b[?25hRequirement already satisfied: pandas>=1.3.0 in /usr/local/lib/python3.8/dist-packages (from yfinance) (1.3.5)\n",
            "Requirement already satisfied: multitasking>=0.0.7 in /usr/local/lib/python3.8/dist-packages (from yfinance) (0.0.11)\n",
            "Requirement already satisfied: appdirs>=1.4.4 in /usr/local/lib/python3.8/dist-packages (from yfinance) (1.4.4)\n",
            "Collecting cryptography>=3.3.2\n",
            "  Downloading cryptography-39.0.1-cp36-abi3-manylinux_2_28_x86_64.whl (4.2 MB)\n",
            "\u001b[2K     \u001b[90m━━━━━━━━━━━━━━━━━━━━━━━━━━━━━━━━━━━━━━━━\u001b[0m \u001b[32m4.2/4.2 MB\u001b[0m \u001b[31m41.9 MB/s\u001b[0m eta \u001b[36m0:00:00\u001b[0m\n",
            "\u001b[?25hRequirement already satisfied: lxml>=4.9.1 in /usr/local/lib/python3.8/dist-packages (from yfinance) (4.9.2)\n",
            "Collecting soupsieve>1.2\n",
            "  Downloading soupsieve-2.4-py3-none-any.whl (37 kB)\n",
            "Requirement already satisfied: cffi>=1.12 in /usr/local/lib/python3.8/dist-packages (from cryptography>=3.3.2->yfinance) (1.15.1)\n",
            "Requirement already satisfied: six>=1.9 in /usr/local/lib/python3.8/dist-packages (from html5lib>=1.1->yfinance) (1.15.0)\n",
            "Requirement already satisfied: webencodings in /usr/local/lib/python3.8/dist-packages (from html5lib>=1.1->yfinance) (0.5.1)\n",
            "Requirement already satisfied: python-dateutil>=2.7.3 in /usr/local/lib/python3.8/dist-packages (from pandas>=1.3.0->yfinance) (2.8.2)\n",
            "Requirement already satisfied: charset-normalizer<4,>=2 in /usr/local/lib/python3.8/dist-packages (from requests>=2.26->yfinance) (3.0.1)\n",
            "Requirement already satisfied: certifi>=2017.4.17 in /usr/local/lib/python3.8/dist-packages (from requests>=2.26->yfinance) (2022.12.7)\n",
            "Requirement already satisfied: idna<4,>=2.5 in /usr/local/lib/python3.8/dist-packages (from requests>=2.26->yfinance) (2.10)\n",
            "Requirement already satisfied: urllib3<1.27,>=1.21.1 in /usr/local/lib/python3.8/dist-packages (from requests>=2.26->yfinance) (1.26.14)\n",
            "Requirement already satisfied: pycparser in /usr/local/lib/python3.8/dist-packages (from cffi>=1.12->cryptography>=3.3.2->yfinance) (2.21)\n",
            "Installing collected packages: soupsieve, requests, html5lib, frozendict, cryptography, beautifulsoup4, yfinance\n",
            "  Attempting uninstall: requests\n",
            "    Found existing installation: requests 2.25.1\n",
            "    Uninstalling requests-2.25.1:\n",
            "      Successfully uninstalled requests-2.25.1\n",
            "  Attempting uninstall: html5lib\n",
            "    Found existing installation: html5lib 1.0.1\n",
            "    Uninstalling html5lib-1.0.1:\n",
            "      Successfully uninstalled html5lib-1.0.1\n",
            "  Attempting uninstall: beautifulsoup4\n",
            "    Found existing installation: beautifulsoup4 4.6.3\n",
            "    Uninstalling beautifulsoup4-4.6.3:\n",
            "      Successfully uninstalled beautifulsoup4-4.6.3\n",
            "Successfully installed beautifulsoup4-4.11.2 cryptography-39.0.1 frozendict-2.3.5 html5lib-1.1 requests-2.28.2 soupsieve-2.4 yfinance-0.2.12\n"
          ]
        }
      ]
    },
    {
      "cell_type": "code",
      "execution_count": 2,
      "metadata": {
        "colab": {
          "base_uri": "https://localhost:8080/"
        },
        "id": "Y3bcwJb4rp93",
        "outputId": "5d201214-284e-4ab4-a0fd-53d7e81406f5"
      },
      "outputs": [
        {
          "output_type": "stream",
          "name": "stdout",
          "text": [
            "\r[*********************100%***********************]  1 of 1 completed\n"
          ]
        }
      ],
      "source": [
        "import yfinance as yf\n",
        "import numpy as np\n",
        "import pandas as pd\n",
        "from sklearn.preprocessing import MinMaxScaler\n",
        "from tensorflow.keras.models import Sequential\n",
        "from keras.layers import Activation\n",
        "from tensorflow.keras.layers import Dense, LSTM, Dropout\n",
        "import matplotlib.pyplot as plt\n",
        "from sklearn.metrics import mean_squared_error,mean_absolute_error , accuracy_score\n",
        "\n",
        "########################################\n",
        "####Pick your ticker and time period####\n",
        "########################################\n",
        "stock_data = yf.download(\"AAPL\", start=\"1990-01-01\", end=\"2022-02-21\")\n",
        "\n",
        "# Preprocess data\n",
        "scaled_data = np.array(stock_data[\"Close\"].pct_change().dropna()).reshape(-1,1)\n",
        "\n",
        "# Split data into training and test sets\n",
        "training_data_len = int(len(scaled_data) * 0.8)\n",
        "train_data = scaled_data[0:training_data_len, :]\n",
        "test_data = scaled_data[training_data_len:, :]"
      ]
    },
    {
      "cell_type": "markdown",
      "source": [
        "# 2.) Create your x_train/y_train data so that your RNN uses percentage change data to make a binary forecast where the stock moves up or down the next day\n",
        "# Build an RNN Architecture accordingly"
      ],
      "metadata": {
        "id": "foHoGy9hq3_o"
      }
    },
    {
      "cell_type": "code",
      "source": [
        "x_train = []\n",
        "y_train = []\n",
        "\n",
        "####Pick your input size and edit to make binary forecast####\n",
        "input_size = 5\n",
        "for i in range(input_size, len(train_data)):\n",
        "    x_train.append(train_data[i-input_size:i, 0])\n",
        "    if train_data[i, 0] > 0:\n",
        "        y_train.append(1)\n",
        "    else:\n",
        "        y_train.append(0)\n",
        "\n",
        "# Convert to numpy arrays and reshape for LSTM input\n",
        "x_train, y_train = np.array(x_train), np.array(y_train)\n",
        "x_train = np.reshape(x_train, (x_train.shape[0], x_train.shape[1], 1))\n",
        "y_train_binary = (y_train > 0.5).astype(int)"
      ],
      "metadata": {
        "id": "X1GvHYhkgu7V"
      },
      "execution_count": 3,
      "outputs": []
    },
    {
      "cell_type": "code",
      "source": [
        "###################################\n",
        "####Build Your RNN Architecture####\n",
        "###################################\n",
        "model = Sequential()\n",
        "model.add(LSTM(x_train.shape[1], return_sequences=True, input_shape=(x_train.shape[1], 1)))\n",
        "model.add(Dropout(0.2))\n",
        "model.add(LSTM(50,return_sequences=False))\n",
        "model.add(Dense(25, activation='relu'))\n",
        "model.add(Dense(1, activation='relu'))\n",
        "model.add(Activation('sigmoid'))\n",
        "\n",
        "model.compile(optimizer='adam', loss='mean_squared_error',metrics=[\"accuracy\"])\n",
        "model.fit(x_train, y_train, batch_size=20, epochs=10)"
      ],
      "metadata": {
        "id": "5qGFB5HfqcVd",
        "colab": {
          "base_uri": "https://localhost:8080/"
        },
        "outputId": "bf11bbe2-f1ac-4b50-9bd3-ac9888e050e0"
      },
      "execution_count": 4,
      "outputs": [
        {
          "output_type": "stream",
          "name": "stdout",
          "text": [
            "Epoch 1/10\n",
            "324/324 [==============================] - 13s 17ms/step - loss: 0.2500 - accuracy: 0.5022\n",
            "Epoch 2/10\n",
            "324/324 [==============================] - 5s 14ms/step - loss: 0.2500 - accuracy: 0.5025\n",
            "Epoch 3/10\n",
            "324/324 [==============================] - 5s 16ms/step - loss: 0.2500 - accuracy: 0.5025\n",
            "Epoch 4/10\n",
            "324/324 [==============================] - 6s 17ms/step - loss: 0.2500 - accuracy: 0.5025\n",
            "Epoch 5/10\n",
            "324/324 [==============================] - 4s 11ms/step - loss: 0.2500 - accuracy: 0.5025\n",
            "Epoch 6/10\n",
            "324/324 [==============================] - 3s 9ms/step - loss: 0.2500 - accuracy: 0.5025\n",
            "Epoch 7/10\n",
            "324/324 [==============================] - 3s 10ms/step - loss: 0.2500 - accuracy: 0.5025\n",
            "Epoch 8/10\n",
            "324/324 [==============================] - 3s 9ms/step - loss: 0.2500 - accuracy: 0.5025\n",
            "Epoch 9/10\n",
            "324/324 [==============================] - 3s 8ms/step - loss: 0.2500 - accuracy: 0.5025\n",
            "Epoch 10/10\n",
            "324/324 [==============================] - 3s 8ms/step - loss: 0.2500 - accuracy: 0.5025\n"
          ]
        },
        {
          "output_type": "execute_result",
          "data": {
            "text/plain": [
              "<keras.callbacks.History at 0x7fd696333490>"
            ]
          },
          "metadata": {},
          "execution_count": 4
        }
      ]
    },
    {
      "cell_type": "markdown",
      "source": [
        "# 3.) Test your model and compare insample Accurracy, insample random walk assumption Accuracy, Out of sample Accuracy and out of sample random walk assumption Accuracy using a bar chart"
      ],
      "metadata": {
        "id": "yFhO9vMjsWPk"
      }
    },
    {
      "cell_type": "code",
      "source": [
        "# Normalize the data\n",
        "scaler = MinMaxScaler()\n",
        "train_data_normalized = scaler.fit_transform(train_data)\n",
        "test_data_normalized = scaler.transform(test_data)\n",
        "\n",
        "# Generate predicted outputs for test data\n",
        "x_test = []\n",
        "y_test = []\n",
        "for i in range(input_size, len(test_data)):\n",
        "    x_test.append(test_data_normalized[i-input_size:i, 0])\n",
        "    if test_data_normalized[i, 0] > 0:\n",
        "        y_test.append(1)\n",
        "    else:\n",
        "        y_test.append(0)\n",
        "x_test, y_test = np.array(x_test), np.array(y_test)\n",
        "x_test = np.reshape(x_test, (x_test.shape[0], x_test.shape[1], 1))\n",
        "y_test_binary = (y_test > 0.5).astype(int)\n",
        "y_pred = model.predict(x_test)\n",
        "y_pred_binary = (y_pred > 0.5).astype(int)\n",
        "\n",
        "# Calculate accuracies\n",
        "in_sample_acc = accuracy_score(y_train_binary, model.predict(x_train).round())\n",
        "in_sample_rw_acc = accuracy_score(y_train_binary[1:], (train_data_normalized[input_size:-1, 0] > 0).astype(int))\n",
        "out_of_sample_acc = accuracy_score(y_test_binary, y_pred_binary)\n",
        "out_of_sample_rw_acc = accuracy_score(y_test_binary[1:], (test_data_normalized[input_size:-1, 0] > 0).astype(int))"
      ],
      "metadata": {
        "colab": {
          "base_uri": "https://localhost:8080/"
        },
        "id": "d_chDrOH8cD0",
        "outputId": "a8e1fa47-7a2a-4de5-e437-1b9b162cdd58"
      },
      "execution_count": 5,
      "outputs": [
        {
          "output_type": "stream",
          "name": "stdout",
          "text": [
            "51/51 [==============================] - 1s 3ms/step\n",
            "203/203 [==============================] - 1s 3ms/step\n"
          ]
        }
      ]
    },
    {
      "cell_type": "code",
      "source": [
        "# Create bar chart\n",
        "labels = ['In-sample Accuracy', 'In-sample RW Accuracy', 'Out of sample Accuracy', 'Out of sample RW Accuracy']\n",
        "values = [in_sample_acc, in_sample_rw_acc, out_of_sample_acc, out_of_sample_rw_acc]\n",
        "colors = ['blue', 'r', 'blue', 'r']\n",
        "plt.bar(labels, values, color=colors)\n",
        "plt.ylim(0, 1)\n",
        "plt.title('Model Performance')\n",
        "plt.xticks(rotation=45)\n",
        "plt.ylabel('Accuracy')\n",
        "plt.show()"
      ],
      "metadata": {
        "colab": {
          "base_uri": "https://localhost:8080/",
          "height": 376
        },
        "id": "pNHInsfH-Iqg",
        "outputId": "f5816431-a475-41bf-c46b-5d5258362806"
      },
      "execution_count": 6,
      "outputs": [
        {
          "output_type": "display_data",
          "data": {
            "text/plain": [
              "<Figure size 432x288 with 1 Axes>"
            ],
            "image/png": "iVBORw0KGgoAAAANSUhEUgAAAYcAAAFnCAYAAABNWoX8AAAAOXRFWHRTb2Z0d2FyZQBNYXRwbG90bGliIHZlcnNpb24zLjUuMywgaHR0cHM6Ly9tYXRwbG90bGliLm9yZy/NK7nSAAAACXBIWXMAAAsTAAALEwEAmpwYAAAzT0lEQVR4nO3de7xlc/3H8dd7Zgxj3BlymZBLoqRMUpQSch90YbpIuaSQSqSSJFIuuZdIyd0oNEKKSJQySBkiodz6GbnkzozP74/P95g1Z52Zs8/M7LPOPuf9fDzOY/Zee+19vmfN2uuzvrfPVxGBmZlZ1bCmC2BmZgOPg4OZmdU4OJiZWY2Dg5mZ1Tg4mJlZjYODmZnVODhYR5O0kqSQNKKFfXeRdH0/lWsDSf+Q9Iyk7frjd5rNSw4O1m8k3S/pJUlLddt+a7nAr9RQ0apB5pnyc7+kA+fiIw8FToqIhSLiknlUTLN+4+Bg/e0+YELXE0lvAhZsrjg1i0XEQmQZD5a0eV/eXKnBrAhMmZMCtFILMms3Bwfrb2cBO1eefwI4s7qDpEUlnSlpqqR/STpI0rDy2nBJR0t6TNK9wFY9vPd0SY9IekjSYZKG97WQEfFH8uL+xvK5n5J0p6QnJF0pacXK7wxJe0n6B/APSf8EXgdcWmoh80taTtIkSY9LukfS7pX3HyLpZ5LOlvQ/YBdJ15ay/6F8xqWSlpR0jqT/SbqpWtOSdLykB8prN0t6V7fPn1iO6dOSpkgaV3l9rKSLyvH+r6STKq/N8u+2wc3BwfrbjcAikt5QLto7AWd32+dEYFHyArsRGUw+WV7bHdgaeAswDvhgt/eeAUwDVi37bAbs1pcCKm0ArAXcKmk88FVgB2AM8HvgvG5v2w54O7BmRKwC/BvYpjQrvQicDzwILFfK/G1JG1fePx74GbAYcE7ZthPwcWB5YBXgj8BPgCWAO4FvVN5/E7BOee1c4EJJC1Re37aUYTFgEnBS+VuHA78E/gWsVH7X+eW1Vv5uG6wiwj/+6Zcf4H5gE+Ag4Ahgc+A3wAggyIvTcOAl8iLb9b5PA9eWx78F9qy8tll57whgGeBFYFTl9QnANeXxLsD1syjbSuVzngSeIC++nyuvXQHsWtl3GPAcsGJ5HsDGPf2t5fFYYDqwcOX1I4AzyuNDgOu6vf9a4GuV58cAV1SebwP8ZTbH+gngzZXPv6ry2prA8+XxO4CpwIgePmO2f7d/BveP2zatCWcB1wEr061JCVgKmI+8k+3yL/KOFvLO+4Fur3VZsbz3EUld24Z12783S0XEtG7bVgSOl3RMZZtKmbp+/+x+x3LA4xHxdLdyj6s87+n9/1d5/HwPzxd6tTDSl4Bdy+8KYBHyWHb5T+Xxc8ACpW9jLPCvHv5maO3vtkHKwcH6XUT8S9J9wJbkBa3qMeBl8sJ0R9n2WuCh8vgR8oJG5bUuD5A1h54u8HPjAeDwiDhnNvvMLr3xw8ASkhauBIjq39Tb+2er9C8cALwPmBIRr0h6gryQ9+YB4LWSRvRwzFr5u22Qcp+DNWVXsinm2erGiJgOTAQOl7Rw6QD9IjP6JSYCn5O0gqTFgQMr730E+DVwjKRFJA2TtIqkjeayrKcAX5G0Frza6f2hVt8cEQ8AfwCOkLSApLXJv797X8ucWpjsZ5kKjJB0MFlzaMWfyYD7HUmjS/k2KK/N1d9tnc3BwRoREf+MiMmzeHkf4FngXuB6soP1x+W104ArgduAW4CLur13Z2AkWet4guzkXXYuy3ox8F3g/DKa6HZgiz5+zASyX+Nh4GLgGxFx1dyUq+JK4FfA3WRzzwu02JRWgvE2ZAf+v8lO8x3La/Pi77YOpQgv9mNmZjNzzcHMzGraFhwk/VjSo5Jun8XrknRCmRD0V0lvbVdZzMysb9pZcziDHMc+K1sAq5WfPYAftLEsZmbWB20LDhFxHfD4bHYZD5wZ6UZgMUlz1XFoZmbzRpPzHJZn5hEVD5Ztj3TfUdIeZO2C0aNHr7vGGmv0SwHNbIC5+eamS9Csdded47fefPPNj0XEmFb374hJcBFxKnAqwLhx42Ly5FmNgDSzQU2tzOsbxObi2iepT7Pamxyt9BAzz3RdgZlnjJqZWUOaDA6TgJ3LqKX1gafKDFczM2tY25qVJJ0HvAdYStKDZHrh+QAi4hTgcjK3zj1kIrBP9vxJZmbW39oWHCJiQi+vB7BXu36/mZnNOc+QNjOzGgcHMzOrcXAwM7MaBwczM6txcDAzsxoHBzMzq3FwMDOzGgcHMzOrcXAwM7MaBwczM6txcDAzsxoHBzMzq3FwMDOzGgcHMzOrcXAwM7MaBwczM6txcDAzsxoHBzMzq3FwMDOzGgcHMzOrcXAwM7MaBwczM6txcDAzsxoHBzMzq3FwMDOzGgcHMzOrcXAwM7MaBwczM6txcDAzsxoHBzMzq3FwMDOzGgcHMzOrcXAwM7MaBwczM6txcDAzs5q2BgdJm0u6S9I9kg7s4fXXSrpG0q2S/ippy3aWx8zMWtO24CBpOHAysAWwJjBB0prddjsImBgRbwF2Ar7frvKYmVnr2llzWA+4JyLujYiXgPOB8d32CWCR8nhR4OE2lsfMzFrUzuCwPPBA5fmDZVvVIcDHJD0IXA7s09MHSdpD0mRJk6dOndqOspqZWUXTHdITgDMiYgVgS+AsSbUyRcSpETEuIsaNGTOm3wtpZjbUtDM4PASMrTxfoWyr2hWYCBARfwQWAJZqY5nMzKwF7QwONwGrSVpZ0kiyw3lSt33+DbwPQNIbyODgdiMzs4a1LThExDRgb+BK4E5yVNIUSYdK2rbsth+wu6TbgPOAXSIi2lUmMzNrzYh2fnhEXE52NFe3HVx5fAewQTvLYGZmfdd0h7SZmQ1ADg5mZlbj4GBmZjUODmZmVuPgYGZmNQ4OZmZW4+BgZmY1Dg5mZlbj4GBmZjUODmZmVuPgYGZmNQ4OZmZW4+BgZmY1Dg5mZlbj4GBmZjUODmZmVuPgYGZmNQ4OZmZW4+BgZmY1Dg5mZlbj4GBmZjUODmZmVuPgYGZmNQ4OZmZW4+BgZmY1Dg5mZlbj4GBmZjUODmZmVuPgYGZmNQ4OZmZW4+BgZmY1Dg5mZlbj4GBmZjUODmZmVtPW4CBpc0l3SbpH0oGz2OfDku6QNEXSue0sj5mZtWZEuz5Y0nDgZGBT4EHgJkmTIuKOyj6rAV8BNoiIJyQt3a7ymJlZ69pZc1gPuCci7o2Il4DzgfHd9tkdODkingCIiEfbWB4zM2tRO4PD8sADlecPlm1VqwOrS7pB0o2SNu/pgyTtIWmypMlTp05tU3HNzKxL0x3SI4DVgPcAE4DTJC3WfaeIODUixkXEuDFjxvRvCc3MhqBeg4OkbSTNSRB5CBhbeb5C2Vb1IDApIl6OiPuAu8lgYWZmDWrlor8j8A9JR0paow+ffROwmqSVJY0EdgImddvnErLWgKSlyGame/vwO8zMrA16DQ4R8THgLcA/gTMk/bH0ASzcy/umAXsDVwJ3AhMjYoqkQyVtW3a7EvivpDuAa4D9I+K/c/H3mJnZPKCIaG1HaUng48DnyYv9qsAJEXFi20rXg3HjxsXkyZP781ea2UAhNV2CZrV4ve6JpJsjYlyr+7fS57CtpIuBa4H5gPUiYgvgzcB+c1pQMzMbuFqZBPcB4NiIuK66MSKek7Rre4plZmZNaiU4HAI80vVE0ihgmYi4PyKublfBzMysOa2MVroQeKXyfHrZZmZmg1QrwWFESX8BQHk8sn1FMjOzprUSHKZWhp4iaTzwWPuKZGZmTWulz2FP4BxJJwEi8yXt3NZSmZlZo3oNDhHxT2B9SQuV58+0vVRmZtaoltZzkLQVsBawgMoklIg4tI3lMjOzBrUyCe4UMr/SPmSz0oeAFdtcLjMza1ArHdLvjIidgSci4pvAO8gEeWZmNki1EhxeKP8+J2k54GVg2fYVyczMmtZKn8OlZQGeo4BbgABOa2ehzMysWbMNDmWRn6sj4kng55J+CSwQEU/1R+HMzKwZs21WiohXgJMrz190YDAzG/xa6XO4WtIHpKGeSN3MbOhopc/h08AXgWmSXiCHs0ZELNLWkrXBUA9vc7FOiJkNMa3MkJ7tcqA2hDi6Nl0Cs37Ta3CQ9O6etndf/MfMzAaPVpqV9q88XgBYD7gZ2LgtJTIzs8a10qy0TfW5pLHAce0qkJmZNa+V0UrdPQi8YV4XxMzMBo5W+hxOJGdFQwaTdciZ0mZmNki10ucwufJ4GnBeRNzQpvKYmdkA0Epw+BnwQkRMB5A0XNKCEfFce4tmZmZNaWmGNDCq8nwUcFV7imNmZgNBK8FhgerSoOXxgu0rkpmZNa2V4PCspLd2PZG0LvB8+4pkZmZNa6XP4fPAhZIeJvMqvYZcNtTMzAapVibB3SRpDeD1ZdNdEfFye4tlZmZN6rVZSdJewOiIuD0ibgcWkvTZ9hfNzMya0kqfw+5lJTgAIuIJYPe2lcjMzBrXSnAYXl3oR9JwYGT7imRmZk1rpUP6V8AFkn5Ynn8auKJ9RTIzs6a1Ehy+DOwB7Fme/5UcsWRmZoNUr81KEfEK8CfgfnIth42BO1v5cEmbS7pL0j2SDpzNfh+QFJLGtVZsMzNrp1nWHCStDkwoP48BFwBExHtb+eDSN3EysCmZ5vsmSZMi4o5u+y0M7EsGIDMzGwBmV3P4O1lL2DoiNoyIE4Hpffjs9YB7IuLeiHgJOB8Y38N+3wK+C7zQh882M7M2ml1w2AF4BLhG0mmS3kfOkG7V8sADlecPlm2vKmk5xkbEZbP7IEl7SJosafLUqVP7UAQzM5sTswwOEXFJROwErAFcQ6bRWFrSDyRtNre/WNIw4HvAfr3tGxGnRsS4iBg3ZsyYuf3VZmbWi1Y6pJ+NiHPLWtIrALeSI5h68xAwtvJ8hbKty8LAG4FrJd0PrA9Mcqe0mVnz+rSGdEQ8Ue7i39fC7jcBq0laWdJIYCdgUuWznoqIpSJipYhYCbgR2DYiJvf8cWZm1l/6FBz6IiKmAXsDV5JDXydGxBRJh0ratl2/18zM5l4rk+DmWERcDlzebdvBs9j3Pe0si5mZta5tNQczM+tcDg5mZlbj4GBmZjUODmZmVuPgYGZmNQ4OZmZW4+BgZmY1Dg5mZlbj4GBmZjUODmZmVuPgYGZmNQ4OZmZW4+BgZmY1Dg5mZlbj4GBmZjUODmZmVuPgYGZmNQ4OZmZW4+BgZmY1Dg5mZlbj4GBmZjUODmZmVuPgYGZmNQ4OZmZW4+BgZmY1Dg5mZlbj4GBmZjUODmZmVuPgYGZmNQ4OZmZW4+BgZmY1Dg5mZlbj4GBmZjUODmZmVtPW4CBpc0l3SbpH0oE9vP5FSXdI+qukqyWt2M7ymJlZa9oWHCQNB04GtgDWBCZIWrPbbrcC4yJibeBnwJHtKo+ZmbWunTWH9YB7IuLeiHgJOB8YX90hIq6JiOfK0xuBFdpYHjMza1E7g8PywAOV5w+WbbOyK3BFTy9I2kPSZEmTp06dOg+LaGZmPRkQHdKSPgaMA47q6fWIODUixkXEuDFjxvRv4czMhqARbfzsh4CxlecrlG0zkbQJ8DVgo4h4sY3lMTOzFrWz5nATsJqklSWNBHYCJlV3kPQW4IfAthHxaBvLYmZmfdC24BAR04C9gSuBO4GJETFF0qGSti27HQUsBFwo6S+SJs3i48zMrB+1s1mJiLgcuLzbtoMrjzdp5+83M7M5MyA6pM3MbGBxcDAzsxoHBzMzq3FwMDOzGgcHMzOrcXAwM7MaBwczM6txcDAzsxoHBzMzq3FwMDOzGgcHMzOrcXAwM7MaBwczM6txcDAzsxoHBzMzq3FwMDOzGgcHMzOrcXAwM7MaBwczM6txcDAzsxoHBzMzq3FwMDOzGgcHMzOrcXAwM7MaBwczM6txcDAzsxoHBzMzq3FwMDOzGgcHMzOrcXAwM7MaBwczM6txcDAzsxoHBzMzq3FwMDOzGgcHMzOraWtwkLS5pLsk3SPpwB5en1/SBeX1P0laqZ3lMTOz1rQtOEgaDpwMbAGsCUyQtGa33XYFnoiIVYFjge+2qzxmZta6dtYc1gPuiYh7I+Il4HxgfLd9xgM/LY9/BrxPktpYJjMza8GINn728sADlecPAm+f1T4RMU3SU8CSwGPVnSTtAexRnj4j6a62lLj9lqLb39afBkHYbfT4DYYDSNPHsPN18jm4Yl92bmdwmGci4lTg1KbLMbckTY6IcU2Xo1P5+M09H8O5M5SOXzublR4Cxlaer1C29biPpBHAosB/21gmMzNrQTuDw03AapJWljQS2AmY1G2fScAnyuMPAr+NiGhjmczMrAVta1YqfQh7A1cCw4EfR8QUSYcCkyNiEnA6cJake4DHyQAymHV801jDfPzmno/h3Bkyx0++UTczs+48Q9rMzGocHMzMrMbBwczMahwchghJa0l6TdPlGIwkLVz+9fdpDklapekyDFZd52Vfs0/4ZB4CJI0GdgHeVJ77/30ekDSsJIu8QdJyEfFK02XqRJIWB/aT9KamyzLYSHoLcAFAX6cJ+CIxBETEs8DLlDklvojNPUmKiFci4n7gamAHFQ0XrRNNAxYD3ttwOQadiLgVGC1p276+18FhEJO0qqRNy9ODgOGSuic/tDmzfOXxb4A3RdFUgTqNpJUkrRwRTwPfAbaTtE7DxRoUJI2qPL0MWL1sb/nmxcFhkOn6z5e0DLA5cJSkw8i7sr+Qd2g2ByrHdhTwa0nflvRZ4ApgLUmfarSAHUTScmRNdpKk7chr0a+ARcrrvjbNIUnLA7dI2kPShsBFwGckvbUvNy+eBDeIlKaOkLQ5sAZwBjkLfk9gfjKz7TRgu4i4qbGCdqDKsd0MeAG4D1gV2Bv4D5kX7LmI2KNr3waLOyBVjuG7gWWBy4F3AZsAo4APA7cD20TE/5oraeepHNt3AVPIJRPGAJ8nZ3VvBVwdEcdLGtZK07Kj8yBSTo73ACcCN0fEkxHxGHBERHwd2I/MZ/UW8N1ZX5RjuxVwFLBoRDwQEddExAeA3wL3AjtJ2sCBoWflGG4KnEkm3XwmIi4HvlF+fgQ8Crwb+j66ZiirnJ+nAm+NiF9FxFnAtsCC5E3iPpJGtdrn6JrDICPpeODvEfGDshrfK8DwiJhWXt8S+GREfKjJcnYaSfMD5wDHRcT1JbAqIqZX9tkFWDMiDmiomANWudCPIhf3OjsifiFpeERMlzSi5GIbTt7ALBIRBzVa4A4jaQnyxu9LEXFj2TYsIl6p1CpOBf4WESe28pm+cxx8HiWbkACGlbvYtSStWtln7TJ80Fo3AlgOGF2eDysXttdV9lkYWNU1srrSV/8c8Ehlc9dxWkXSkiXQPgW8S9KCrjn0yUjyeP4dQNLIEhgWq9RkHwJanuvkk7iDVTpIV5O0eJnPcBO5XvfawAhJbwZ+AsxX3nY3MD4inmik0B2icmwXkbRAGQ58JvBBSWuXO90NgQskrVhqFtOBr3uocKocw6UrAfMRYEdJoyPi5TI66URmBN1Hgb0j4jk3z81a5djODxAR/wH+Bny5HNuXJL0XOFfSYpIWI29ezmv5d/j4d7bSTPRt4Jfk8Mq9gR2AjwFPAisD346IS1rtiBrqKtXw8cDOZMr575Fp5TchO/YvAT4AfDEiLivv8/HtRtIWwMHkXJAnI+Lo0ryxDPAE8Gbg0Ii4uMFidpTK+bk1OSLxZeAIYDVgG+CdZPPdfsD+lfNz/oh4seXf4+DQucpdV1en0wTg48D95d/p5GiFYRHxd4+g6RtJ7wcOI79sJwJrAl8j5zS8lbwLeywi/tx1F+fjO7NSs/ohsCM5Q38bYFJE7K+cubsMMDUibvb52Tcl6B5BroFzIXAP8N3y70eBl4C7I+LqOb1pcXDoMJW7htWB1wIPkjWGI8lx4weQS69+NiLubK6knadybEUG2/vJBeW/TI4V/zRZSzs/Il5orKADWOUYvhZYh2zGHEset/3IWsSdwOccDPqmGkAlHUM2EY0hj+kUsubwxYi4eV78Pvc5dJBu48S/R94l3AW8DzgkIm4H/kmOu1+4uZJ2nsqx3YYMBOeRx3ZX4FMRcQx5oduJMlHL6irDVb8B/JUMsDsDn4+I68rzNwBvbKqMnahyfu4g6QBgf/J7fgDw/ojYDVgB2FvSovPid7ZtmVCb98rJ8TayrfunEXF/Gf63OLCFpAC2Bz4eEX9rsqydphzbdYHdge+WO7T/SnqK7EC9GggyCD/aZFkHstLUuT1wTjk/R5OdzSuXTumVgc9ExN0NFrPjVL77nwC+V0YideVMe7ukh8lgfEpEPDUvfqdrDp3n7cDWwPJluNp08i5tFHlX+y0HhtZVRn0MA7Yka2FPl23zkTWI1wGnAad2jSG3unIs9yVTtYwubd1do7wmkE1Lpzgw9F0JsnsCb4yI35XNLwIXk7OgJwE/iog/zbPf6Wa/ziDpDcC7I+KHkvYkO/e+Dtxehq0NJye7veTOvb6R9E5yCPB04ASyjfwLEXFvCcAvSRobEQ/42PasnJ/LADcAJ5FpWr4NPFzuehcFiIinfAz7RtKaEXGHpDWAU4DbImLf8tqi5I3hkhExZV7+XtccBrjK+PB1gLdJ2i0iTiFTNhwMvEVlpmlEvAQeNTMH9iL7F4YDXwRuA46QtFrlmD5Q/vWxrVCuaTGSHFL5cWB94HNkv8z+ZDs4EfFUV3OHj2FryrEdRiYnPCMi/g58BlhM0lHw6nH9z7wODODg0AmWLv9OJIdRri1pj9JB+mfgEGZMILI+kLQgQER8FPgdcEt56TCy4/QozZz62OpGlgB6IRlUdySbPncja2Bf6ZqoZX02ogxBXYe8MfxBGYF4BLCSpOPa+cvdrDSASVqSvGgdGRFnlqajHckJbhdHxGnKfPj3NVrQDiTpjcB44JKuuy5JZ5GTssaRN05jI+IfzZVyYFOmDpkI7BgR/1Sm4f4wGRxOIIPtGhFxW4PF7EjKDAdvBq6KiEfKTcrtwK8iYi9Ja5HBo23H1jWHAabSQboC2TH6VWBfSTuVpqNzybbxDUs7uANDiyrHdmHy2K4NbFnaywE+Rc5ruD4iXnBgqKscw8XJOTa/As4sNykPk8FiVfJYjnZgaF23wRErANsB75X0moh4HvgguS7DMRExpd3H1kNZB5jKWPuvALtExCRJ04HDS9vuZLIZ6aCudnDrXWWc+PvJdtsPAocDXyivB9mx9xPgysYKOsCVY7gtOQt3P3Kk3MtkDp8PkMfwUTJ77ePNlbSzVM7PTYEtI+ILkhYiRyYi6SKyk/84MiC3v0xuVhpYJL2VHDb52eqwNGUSre8BzwDHRsRFDRWxYynTOfwE2CMirinb3kTmSloK2IgMyL/2iJqelZFdJwH7RMQNle2HkE2e08kbl0saKWAHUy4kdTywb0T8umzbEXg/uSbDhsCEiPh9f5yfDg4DjKSNgA9FxN6lnfFFSsbjcicxMiIe98Wr78oQ4AUi4rgyh2F6mUy0CLAQsETkLHObBeVSqKtExNckLUCen101ipXJY/pvn599U5qUDgNuikyS+WqSPEmrkClypkXEH/qrTO5zaFilnfHNyrS6AaxbJhA9X0YrbFDuIJ7tqqr7i9e7yrEdUzY9A2wtaZmIeLkEhvcAa0XEww4MdZVjuErZ9Ao5KZDSLxPAOyStFxH3RcS/y2s+P3tRObajy/Gan+wDUyUwvA14OiKu68/AAA4OjSt3XFuR2StXjcw/83fgz5LeJWkHsinkSX/h+qbSf/MTSSsBfwBuBj4qaSVlZtCjyfkN1oNyDDcHTi81gwvI4dQnSlqhNHeeTS42Yy2q9DFsA3ynjEy8kBwosVPZZ10yI/AKjZTR15tmlS/cL4Ddu/UxHA4sQa7c9MOI6JdOqMFE0vrA94G9IuKPZdvmZN/CJsBzZMep1xKYhTKk8mfk0rI3lG0LAecDU4FVgO9ErgVtfaBMoHkC2X/ze2WKjJ3IPoalys/XI+IXjZTPwaEZmrG+6zrkl2vzsn1UGbZGT89t9lRmi5fHOwDrR8QBkhaMXKaya6jgkuSN8WNuH6/TjPWdtwC2j4g9SjPI/BHxQuX8XToiHvUxbE238/PLABHxXeVqgy8oJwyOAFYCnouI+5o6tm5W6keSVpG0bflCdS2+8Q/gZUkfAoiI5yW9T9J3S6fpS40VuIMol+pcquuLVyxILtJDJTC8g8xRNTUiHiuv+aJGzq0pTW1UjuODwJqS3h7phTLcctfyuo9hCyQtAzMdV8j+xSXL42nl3zcCr4mcx3BfeU8jx9bBoX8dS1bRfylpS0mvi8xaeQmwvqQTyp3aScBvS6fp9Nl8nvFqxsrzgGsk7VaGBBIRZwMLS7pQ0upl+zlNlnWgKjci1wCXSTpb0lhJi0dm+L0SGC/pE6Wp7mjgXoDwsqi9Uk4YvE7SOZK2lzS2vHQpsLOkTwPzlxuXC4DFGirqTNys1I/KF+tDZJK3TcnRM7cDZ5B3DFsACwC/ibLuq/WuNBP9kOxHOJRM+HY+uabAPyV9nxwJsjJwtNvHeybpE2TKhtHkHe3jwI+B/yMT6n0UeJ48rpc0VMyOU0bL/ZK8GT+fXDPkC2TQXY0ccHIXeQ34ZkT8sqGizsQzpPvXv4F1yVrBh5QzTS8hl/t8ETgsIv4HMy8JaLNWjtMrkr5Krn53J5kb6afARZL+SK6t+xQ5Tvx/zZV2wLuH7BD9ZET8R9JB5AivL5Gj5bbWjBTmPj9bFBFTS//CfsDPyQSFXyKz155JLt71MjAqBlBaeDcr9ZPyH/4w8B3gk2V8/cFkmoxJ5Miktbv2HwgnRycowwEFPEsukbps6V94M1mbGEHOOl3IgWH2ymikW4GDlGsHjCdn5T8B7KacTf5y2dfnZ9/cSWb6VURcBaxFrn3xFTKNS8QASwvvZqV+VC5ii5Enw/ZkFfKURgvVgbruXnvYvjE5VvxF4KiIOLZsXyEiHuznYnaUyrj7lch8SZuQy1F2HcMFIuKFJsvYKaojkrptP4BMSPgKcHpEHKPMgjA2BuDqeK45tFEJBq8qoz2eICdiPd0VGJSpuK0FkpYGfli+VNXFkIiI35LzGq6KiGO7jqsDQ8+q52flbvVfZF/YPyuBYbgDQ2skLQ8cUHmuruMcEUcCdwM3lMAwPDILwoALDODg0BaVL92obtu7LlanA7dJ2ntWdxnWs4h4FFiDbDKi9DdUg/D1wBjNWF/buqlcrKLb9uFl20HAApK2LPv5OLZuJHCApN3g1RvCqJyjk4CuQDugR3o5OMxjler5+4EfSfpiZQ7D9MqdxG+Ba/3Fa42kxTQjR9JWwKKSPg4zX+Qioivd9rr9XMSOUDk/N5Z0tKQJktaDV8/PYeTF6zeU4arWO0mjlBNW7yPTwU8oQ1OBmc7Ry4DtJK0OqIePGjAcHOahyhfvXWRH3vHkVPgtVJZK7LqTAE4NJ3rrVYmliwN/A46UtFlk8sHLgDeWZqaufYcBRMQWUdJl2AzdblxOAP4E7A3sIGkEZE0sMunbdyPXLLZelKakPwD7SFoxIq4ma7AbSlqwq9agnFX+CPCGiLh7oM8RcXCYB5Szc19bvnjDgNXJYWuvkOPFD4mIF5WruwGuqreq0k9zNjAG+GapMfyBrB1sCjOGtDZX0oFL0mvg1ZFdI8llPD8MPEDOqzkxIqaVIEzZ95lGCtuBIuIhckTXFsAZypUF/wC8F1ixHPfhlfPz2YaK2iee5zBvfBz4lKSNI+J+SVPJFZteADaLzD2zDbCWpO/1NNLG6iQtAbxULlSnkV++O8g1tOcjx+UfJemuiJjcXEkHvB+USsMOZY7CM+TkNgHbRMTDkrYm+xkucpBtjaQFyfNzGjksfXXyvPwGOdltJHCqpC0j4umu9w2Uoaq9cc1hHoiIw8j0DRcps6xeR1bZLyfzJq0HfBv4mwND70pT0nzkF+xISdtHxL3kl22DiNgVeBi4j8xau7dy4Rnr2QeBhSSdWZ7/BvgfcEEJDG8HjiInujkw9KKcn4uS3+99lPmo/kTOrfkXsA8zJmRuUPYZ0P0LPfE8h3lI0mHk3e12ZA72bchmjyeBkyLiF13tvo0VsgOorIJV+hN2BN5BXsz2Iucx/C4iji/7fhu4urTz2iyUkXJXkk1JnyVn5W4FLEteyA6JiEubK2HnqPTdbELOB1mVTLt/FZkvad+IuEHSsuQM6MMi4nfNlXjOODjMpVIreD3w54i4S5nGYXvgA5HLJS4NvBwRTzgw9E45M/c4MhvoXyLipNLh90Nydu7PyOB7WETcVnmfj21F5QK2FrAIMJnM/HkZeWw/Q2YFfT3wTAygtA0DWTk/9yPXsvh5RNxcgsSp5DnaNTv/6xHxSOX/oeOOrZuV5oJyFayfkmkGvlVqDkeQ+ZKuUmZdfbR0qHZMW2NTJL2evNP6DXkMPyHpIxHxUERsDdxC3qltB3xQM0+A87EtKhekTclgegTZZ/MRsrawHNmk9EpE3BkDLG3DQFU5P/9Ddir/VNKbI9NhrE+mxOhKrrl+9b2deGzdIT2HlCtkfQP4SETcWsY0bwPsEhGHl5Efy+Gx4i2RtAiZnfaaiDimbFuIykTCiPiWci3jh4Ab3T7esxIY1iXvcMeT5+CWZJPnvWXbNeXCdtusP8m6KOfYTATOrJyfr5CrtVEGnXwWeBuwDDnLvCODQhcHhzlQ2m/XILN/bkwmK7uRvHPYBPhJRHypuRJ2noj4n6SLgXdK2iAyCdzbyBrC5mRTyFnA3RFxELgpaVbKnJpNyKGUi5dhqteRfTdbljkg726yjB3ocbKDeYUybP3fZJPcxpK2A64G/hgR10i6tlObkqrcrNSiykSWJcjUuhPJDtItJO1UToI7gWUlLdmJoxOaohmT144kJw99RdLR5AXsM8DpZDDen+z8o+zfsV+8ea1yfo6KnMR2DHAKcLCkNSLiSTJV9GrK2bzO59WiMnltOjlkfQlg/9K3uA5wMTly7lvASaUpOaDzz093SPeBpO2BL5LLT34lIn4taQI5DPA6sop5okd99F35Ar5SHu8N7Al8IyJ+XraNINNuP9lcKQc2SePJOSDDyOyf08l1Az5BdpZuTc589vnZR5qxZvZ8wMnAe4CPRcSfy+vLkvHgPw0Wc55ycOhFpXNvJNms8R3KimLAPhFxmXIFrQlkNtCjGyxux6lWvTXz4utfADYiU5BcHxEvN1jMAatyfi5BjkQ6kOx4Xpuc3/Bf8pxdDzguIibKyR5b1u38HFGa6EaQHfxPklmA7+n0WkJP3KzUi/LF24yc2PIscFtEXEQ2cRxbJmj9lDxZxpe7N+tFpdmt2uE8XTNy/BwL/JlcDGV0/5ewM5Tzc0NgQ3K+x+8i4tPkpKwLyJQjhwAXkQv2rOrA0Luu87N60e8KDJEzovcAutJzz99MKdvLNYdZqNyRrU1ZvB54E5lN9eiIeFbSjmST0lvIMeQbA5O7hgZazyrH9v1kk8dk4IGIuLC8Xm1iWjky06VVVI7h28mJgX8m0zd8LyLOKPucQg6aeCc5guZDwMTw+hazVTm2G5OjvG4m17foakIaXm5k5gPWHKwjvhwcZkOZXfVzwFkRMamMmnk/WVU/LiKekfSarnbGTh+d0B8qX7x3kR2mnwIOJYenfqZ0ps5yNS2bQdK7gR2AiyLiOkk7k4Hghog4q+yzVkRMKY99THvR7cblGOCbwOeB3wMHlVrDq01MzZW0/dysNHsvk9X1jcrzq4ErgLHkiIVh5ExJoPNHJ7ST+pi51hexlryNDK6vLc9/Ra5LvJmkT5Ztd1SaSHxMZ0F9zFw72AMDeJ7DTCp3DcsCz0fEjZK2Ai6U9PeIOE3Sb4HhwL/Ck7D6wplr51Ll/FwsIp6MXGryReBrkv4SEbdLupI8P28G37D0gTPXduOaQ0X54o0nRyWdLmnXiLiFvIPYT9LeETEtIq6IiDuaLW1nCWeunWvl/NwGOE3S9yWtHxEnkcNUz5W0TuQyqudExN+aLW3HcebabtznUFHacI8mO6G+Rc4w/XFEHFlOjolkM9ODviObM3Lm2jkm6X1kO/j25Oi4keQxmyjpy8Bu5OCIZ338+k7OXDsTB4cKSR8gT4xlyEXWTwD2JVPxfhOYPyL+11wJO5OcuXaulX6aA8g72mXIvF6XApsDJ0fEeZJWioj7mytlZ6k00zlzbQ+GdHConBxvJauL9yoXjTmZvCO7VdKPgMWB/fzF6ztl5trvA1PIzue7ga8DXyWHsW4euZCPdVM5P1cjL1YvkhexM4A9Sj/NDcA/gS9Hrk9sLagc203Jm8D/A+4ng++5ZOB9ISI+2FwpmzWk+xzKybElOU58TNn2AvAS8HVJG5E5fY5yYOg7zZy59oPAseQ5t0tEHA5MIjPXWg/K+bk1mb9ntdLW/SKwKLCjpDXJDv0THBj6phzbaubaTciJghuS6bbHA0tLenNzpWzWkA4OklYHjgS2i4g/SXp9qUWcAPwbOBw4MiJubLKcnUj1zLWQmWvvJb+IRMSXIuL6Zko48EkaR6a+2DEi/lpG0S1Grle8FdnBf0J4/ew+Uw+Za8lBEk+SmWunR8S7B+sEt1YM9aGsj5EdUB9SJtB7F7mQx68j4vOSxkTE1KHUzjg3KlX1JciF1ydKGgV8XNJDEXG+pDuBj0haEnjcx3W2XibPz3GlhrsDGVzPKo+XLsOCfX62oHJ+joqI5yUdQ9ZcD5a0X0T8XdJtwHblvH1pKM8NGdI1B7INfAqZSO8GcgTNteSi9ZDBw2PFW1S+eNuT6+n+TtJmkXmnTgeOlnQu2cx0bET818d1BklrlGbMrucic3k9CexKLly/F3AHsEhEPNfV1Onj2JrKUPUzJf2czNn1NeAm4ApJBwJ7k0OBnx/KgQGGcHCQNF9k+udzyDbwy8gg8SkyT42/dC3qmoFbZpbuRKYcORw4RdJWEXEe+SVcgqyVDZnhgK0os3MvB0ZrRuLBiIh7yGalzSLXD5lG5kd6tLHCdqDK+bkEmbX2JPLG71dk/813yBuabclmukvl9S6GRrNST9XuiHhZ0orkeOYTJXUND/xWRFzpqnrryh3ZZmRiwq7MtbeWL+WxkkZGxE/LrNPPS/pHRPyi0UIPLK8h07JMA46XdAA5UmZ6OU+RtAE5x+EbEXFtg2XtOOX83JC8Obk6In5H1myPIzPXTiAz1+5GZq69pQTmIW3IDGUtE9zeAfySbLedTs7QPTcijpI0muyYetCBoTWVNlxnrp1Lkn4HvBXYOSIu7uH1seQKhHf7/GxN5fx05to5MKiDg2ak1t0A+AHwN3Kc+IVk7plRHukxd+TMtXNFM1YYO5JcoOdW4PsOnvOGnLl2jg3KPgdJi8Kri8e8CTgM+FREfJRMgfEOYF2yBvHqGsY2R5y5dg50tYMDK0taDjg8IjYnF5A5sGyzuefMtXNo0PU5lPHLt0g6KXI1sdeQi9LvRDZnnCXpFTLtwAhJZ4WXoGxZparuzLVzoRzD7ciV7p4H/iHpcrLd+1TgEEnfjIiHGixmx6mcn85cO5cGXXCIXBPgY8AvJD0dET+S9ClgH0n7RsTxEXFOGY1wqwND31SGA+4DPCXp8og4XdKHgXMkzR+ZKfSKZks6sElaCvgSsAuZumFj8oblXnLI6k/JkTQODn1Qzs9tgJ2VaeHPjIiTyiiwcyXtHBF/kXSOv/uzN+iCA0BE/LHczf663EmcVmqNe5aL15ERcWYvH2M9KG24X2NG5tr9JS0Zmbn2E8BESb/AmWt7M5JcROaJiHhc0rXAe4BNIuI2STu6iaPvlJlrv8WMzLVHllaE40qrwoWS3kKOqrPZGJTBASAibirDK39dapo/KncPe0maSDZ5+OLVd2PIiULvIEfXfAvYV9JiZObaN4Uz1/Yqco2Aa4EvSToyMoneLcDa5Tz1udlHpX/rbeSkwTeQabYvBT5XOpq/K+mCiHimyXJ2ikE9WglA0tvIFLzfiIgfSFoqIh5rulydotKG68y1c6A6+kVl3eHKMV2XHEnzXjLT6leA3SPiquZK3Fkqx9KZa+exQT9KJyJuImc+HlXGiv+34SJ1lPLFc+baOSBpPmB3Sa9VZvc8XJWZtxFxM5n48afA/MCuDgx9U85PZ65tg0Ffc+giadGIeKrpcnQaZebai4AJEfE3Sa8nc9I8D3yanEB0ZERMarCYA5ak95Od8/eRa1f8o+EiDSrKzLVnkJlrp5RRdJAjFL9GruJ2cHhGfp8NpeDQVf30JKw+UOaj+RrZgTeCmTPXniZnru1R5Xybn1y34p3A2yIzf87XNVLGk67mTqmR7Qz8FViamTPXXocz186xQd+s1KXrxPAJ0mfOXDsHSmBYB3g3OXJmZ+BPkjaKzJe0hqTRDgytkzPX9qshExys7+TMtXNrI2B/YKPIfEl7AZdL2pucqb9ak4XrJHLm2n7n4GDATOkcXhUzMtceCixbRtfMlLm2v8vZCVRSX0TE8WRH6Z6StoyIs4GPkB34X4qIvzRXyo7TPXPt6K7O/dJE15VD7VScuXaeGDJ9DtY7OXPtXCsdoocDN0bEqWXb3mRq+K9GxCXVPgdrnZy5tl85OAxxcubauSLpdcAWwNPAfyPispKuZV3gppiRGvpX5BDLXT3Ppm/kzLWNGLQzpG32uob2Rj1z7WRJHydH10DWIl79gjZV3oGojKGfRE6yfIlcG/sUcgGZl4ENJS0EXE+Otf+OA0PrKnf/K0t6nsxc+5SkM8nMtYdHxMMNF3PQcp/DEKQZmWu/UDZVM9cSmef+emBTcrH1+RwYZqZMC38KecHaNyL2B95ODvXdETibTN2wKfAT4PSIuLGp8naiMuJrO+Dc8nO0co3y3ci5NodIWr7BIg5qrjkMQeHMtfPCi+TQyYkAkhYofTG7An8EpkTERcAvJS0fEQ+5Hbxv5My1jXJwGKLCmWvn1iiyX+E9wGUR8YJyrewHJJ0ErNK1Y5Q1GRwY+syZaxvkZqUhLDLv1GZkWuPdIuI3wI+Ad0tayUNVZy0ingCOBz5QJrtBju6CzKg6qolyDSalP+FaMnPt0qW/5hZgbNdcB2sfB4chrhIgvi3pMxFxBTnh7X7f6fbqIuARsrb1vtK5/05gT+D3zRatc1STEXZd9Cs3JueRTXiXSNoD+Drwy4iY5lpDe3koqwEgaX3gKjIPvhfqaZGkZcgO6L2Am8jjd2g40VtLlJlrdyVnPy9OThL8KvBK1zlYOv93IpuZpkTEbxsq7pDi4GCvcubaOVfSOwAs4ERvfePMtQOT2+2s6n8w0/hya1FE/Kfbcx+/XlTOs2uB35Bza4aX15y5tmHuc7BXdV3QfGGz/lDmMayDM9cOSK45mFmTNgK2AkZExMUlf9flkr4M7EEGjL80WL4hy8HBzPqdpOUi4uGIOF7SS+SIL0XE2ZKeJmeWO3NtgxwczKxflcy1h0m6MSJOjYgflOGsR5eJhJdIutwz85vl0Upm1lbOXNuZXHMws7Zx5trO5ZqDmbVFmbx2KfCTiPhJ2bYC8GNyBvlhZGf07sBrgYMj4tKGimvduOZgZu3izLUdzPMczKxdqplrqWauBZy5doBzcDCztnDm2s7m4GBm7eTMtR3KHdJm1lbOXNuZHBzMrF84c21ncXAwM7Ma9zmYmVmNg4OZmdU4OJiZWY2Dg5mZ1Tg4mJlZjYODmZnVODiYmVnN/wPvpJxPXPmUMwAAAABJRU5ErkJggg==\n"
          },
          "metadata": {
            "needs_background": "light"
          }
        }
      ]
    },
    {
      "cell_type": "markdown",
      "source": [
        "# 4.) Plot in and out of sample accuracy"
      ],
      "metadata": {
        "id": "8bncNwh8tKiE"
      }
    },
    {
      "cell_type": "code",
      "source": [
        "# # Make predictions on full dataset\n",
        "\n",
        "# test_predict = model.predict(x_test)\n",
        "# test_predictions = (test_predict+1).reshape(1,-1) * np.cumprod(y_test+1)\n",
        "\n",
        "# train_predict = model.predict(x_train)\n",
        "# train_predictions = (train_predict+1).reshape(1,-1) * np.cumprod(y_train+1)\n",
        "\n",
        "# plt.plot(stock_data[:training_data_len- input_size].index, np.cumprod(y_train+1), label=\"Training Data\")\n",
        "# plt.plot(stock_data[:training_data_len- input_size].index, train_predictions[0], label=\"Training Predictions\")\n",
        "# end_val = np.cumprod(y_train+1)[-1]\n",
        "# test_predict = model.predict(x_test)\n",
        "# test_predictions = (test_predict+1).reshape(1,-1) * (np.cumprod((y_test+1))*end_val)\n",
        "# plt.plot(stock_data[training_data_len+1:].index, np.cumprod((y_test+1))*end_val,label=\"Test Data\")\n",
        "# plt.plot(stock_data[training_data_len+1:].index, test_predictions[0], label=\"Test Predictions\")\n",
        "# plt.xlabel(\"Date\")\n",
        "# plt.ylabel(\"Stock Price\")\n",
        "# plt.legend()\n",
        "# plt.show()"
      ],
      "metadata": {
        "id": "d698mdExtfHp"
      },
      "execution_count": 7,
      "outputs": []
    },
    {
      "cell_type": "markdown",
      "source": [
        "#5.) Write an observation/conclusion about the graphs from Q4 and Q3"
      ],
      "metadata": {
        "id": "bK_jyyEEtTUB"
      }
    },
    {
      "cell_type": "markdown",
      "source": [
        "A model with high in-sample accuracy means that it fits the training data well. However, this does not necessarily imply good performance on new data, which is clearly the case here. An out-of-sample RW of 1  suggests that the model does not provide any useful information beyond what can be obtained from a random walk model."
      ],
      "metadata": {
        "id": "TkORSmuRpvgu"
      }
    },
    {
      "cell_type": "markdown",
      "source": [
        "#6.)Test your model and compare insample Accurracy, insample random walk assumption Accuracy, Out of sample Accuracy and out of sample random walk assumption Accuracy using a bar chart"
      ],
      "metadata": {
        "id": "XB9Cd6rznzRQ"
      }
    },
    {
      "cell_type": "code",
      "source": [
        "print('x_train shape:', x_train.shape)\n",
        "print('y_train shape:', y_train.shape)\n",
        "print(model.layers[0].input_shape)\n",
        "print(model.layers[0].output_shape)\n"
      ],
      "metadata": {
        "colab": {
          "base_uri": "https://localhost:8080/"
        },
        "id": "uJxaCTlQiITR",
        "outputId": "79f909c7-3db7-467e-b757-25262ccd7afe"
      },
      "execution_count": 8,
      "outputs": [
        {
          "output_type": "stream",
          "name": "stdout",
          "text": [
            "x_train shape: (6472, 5, 1)\n",
            "y_train shape: (6472,)\n",
            "(None, 5, 1)\n",
            "(None, 5, 5)\n"
          ]
        }
      ]
    },
    {
      "cell_type": "code",
      "source": [
        "import itertools\n",
        "from sklearn.model_selection import GridSearchCV\n",
        "from tensorflow.keras.wrappers.scikit_learn import KerasClassifier\n",
        "\n",
        "# Define a list of input sizes to try\n",
        "input_sizes = [3, 5, 7, 10]\n",
        "\n",
        "# Define a function to build and compile the LSTM model\n",
        "def build_model(input_size):\n",
        "    model = Sequential()\n",
        "    model.add(LSTM(input_size, return_sequences=True, input_shape=(input_size, 1)))\n",
        "    model.add(Dropout(0.2))\n",
        "    model.add(LSTM(input_size, return_sequences=False, input_shape=(input_size, 1)))\n",
        "    model.add(Dense(25, activation='relu'))\n",
        "    model.add(Dense(1, activation='sigmoid'))\n",
        "    model.compile(optimizer='adam', loss='mean_squared_error',metrics=[\"accuracy\"])\n",
        "    return model\n",
        "\n",
        "# Create an instance of GridSearchCV with the parameter grid and model builder function\n",
        "estimator = KerasClassifier(build_fn=build_model, epochs=1, batch_size=20, verbose=0)\n",
        "param_grid = dict(input_size=input_sizes)\n",
        "grid_search = GridSearchCV(estimator=estimator, param_grid=param_grid, cv=5)\n",
        "\n",
        "# Fit the GridSearchCV instance on the training data\n",
        "grid_search.fit(x_train, y_train)\n",
        "\n",
        "# Print the best input size and corresponding mean test score\n",
        "print('Best input size:', grid_search.best_params_['input_size'])\n",
        "print('Best mean test score:', grid_search.best_score_)\n"
      ],
      "metadata": {
        "colab": {
          "base_uri": "https://localhost:8080/"
        },
        "id": "gXoHI1l4gYnP",
        "outputId": "b88f181b-f4c3-47d8-d828-1c7257a14d67"
      },
      "execution_count": 9,
      "outputs": [
        {
          "output_type": "stream",
          "name": "stderr",
          "text": [
            "<ipython-input-9-124ab9278d69>:20: DeprecationWarning: KerasClassifier is deprecated, use Sci-Keras (https://github.com/adriangb/scikeras) instead. See https://www.adriangb.com/scikeras/stable/migration.html for help migrating.\n",
            "  estimator = KerasClassifier(build_fn=build_model, epochs=1, batch_size=20, verbose=0)\n",
            "/usr/local/lib/python3.8/dist-packages/sklearn/model_selection/_validation.py:372: FitFailedWarning: \n",
            "15 fits failed out of a total of 20.\n",
            "The score on these train-test partitions for these parameters will be set to nan.\n",
            "If these failures are not expected, you can try to debug them by setting error_score='raise'.\n",
            "\n",
            "Below are more details about the failures:\n",
            "--------------------------------------------------------------------------------\n",
            "1 fits failed with the following error:\n",
            "Traceback (most recent call last):\n",
            "  File \"/usr/local/lib/python3.8/dist-packages/sklearn/model_selection/_validation.py\", line 680, in _fit_and_score\n",
            "    estimator.fit(X_train, y_train, **fit_params)\n",
            "  File \"/usr/local/lib/python3.8/dist-packages/keras/wrappers/scikit_learn.py\", line 248, in fit\n",
            "    return super().fit(x, y, **kwargs)\n",
            "  File \"/usr/local/lib/python3.8/dist-packages/keras/wrappers/scikit_learn.py\", line 175, in fit\n",
            "    history = self.model.fit(x, y, **fit_args)\n",
            "  File \"/usr/local/lib/python3.8/dist-packages/keras/utils/traceback_utils.py\", line 70, in error_handler\n",
            "    raise e.with_traceback(filtered_tb) from None\n",
            "  File \"/tmp/__autograph_generated_filevd5txmnc.py\", line 15, in tf__train_function\n",
            "    retval_ = ag__.converted_call(ag__.ld(step_function), (ag__.ld(self), ag__.ld(iterator)), None, fscope)\n",
            "ValueError: in user code:\n",
            "\n",
            "    File \"/usr/local/lib/python3.8/dist-packages/keras/engine/training.py\", line 1249, in train_function  *\n",
            "        return step_function(self, iterator)\n",
            "    File \"/usr/local/lib/python3.8/dist-packages/keras/engine/training.py\", line 1233, in step_function  **\n",
            "        outputs = model.distribute_strategy.run(run_step, args=(data,))\n",
            "    File \"/usr/local/lib/python3.8/dist-packages/keras/engine/training.py\", line 1222, in run_step  **\n",
            "        outputs = model.train_step(data)\n",
            "    File \"/usr/local/lib/python3.8/dist-packages/keras/engine/training.py\", line 1023, in train_step\n",
            "        y_pred = self(x, training=True)\n",
            "    File \"/usr/local/lib/python3.8/dist-packages/keras/utils/traceback_utils.py\", line 70, in error_handler\n",
            "        raise e.with_traceback(filtered_tb) from None\n",
            "    File \"/usr/local/lib/python3.8/dist-packages/keras/engine/input_spec.py\", line 295, in assert_input_compatibility\n",
            "        raise ValueError(\n",
            "\n",
            "    ValueError: Input 0 of layer \"sequential_1\" is incompatible with the layer: expected shape=(None, 3, 1), found shape=(None, 5, 1)\n",
            "\n",
            "\n",
            "--------------------------------------------------------------------------------\n",
            "1 fits failed with the following error:\n",
            "Traceback (most recent call last):\n",
            "  File \"/usr/local/lib/python3.8/dist-packages/sklearn/model_selection/_validation.py\", line 680, in _fit_and_score\n",
            "    estimator.fit(X_train, y_train, **fit_params)\n",
            "  File \"/usr/local/lib/python3.8/dist-packages/keras/wrappers/scikit_learn.py\", line 248, in fit\n",
            "    return super().fit(x, y, **kwargs)\n",
            "  File \"/usr/local/lib/python3.8/dist-packages/keras/wrappers/scikit_learn.py\", line 175, in fit\n",
            "    history = self.model.fit(x, y, **fit_args)\n",
            "  File \"/usr/local/lib/python3.8/dist-packages/keras/utils/traceback_utils.py\", line 70, in error_handler\n",
            "    raise e.with_traceback(filtered_tb) from None\n",
            "  File \"/tmp/__autograph_generated_filevd5txmnc.py\", line 15, in tf__train_function\n",
            "    retval_ = ag__.converted_call(ag__.ld(step_function), (ag__.ld(self), ag__.ld(iterator)), None, fscope)\n",
            "ValueError: in user code:\n",
            "\n",
            "    File \"/usr/local/lib/python3.8/dist-packages/keras/engine/training.py\", line 1249, in train_function  *\n",
            "        return step_function(self, iterator)\n",
            "    File \"/usr/local/lib/python3.8/dist-packages/keras/engine/training.py\", line 1233, in step_function  **\n",
            "        outputs = model.distribute_strategy.run(run_step, args=(data,))\n",
            "    File \"/usr/local/lib/python3.8/dist-packages/keras/engine/training.py\", line 1222, in run_step  **\n",
            "        outputs = model.train_step(data)\n",
            "    File \"/usr/local/lib/python3.8/dist-packages/keras/engine/training.py\", line 1023, in train_step\n",
            "        y_pred = self(x, training=True)\n",
            "    File \"/usr/local/lib/python3.8/dist-packages/keras/utils/traceback_utils.py\", line 70, in error_handler\n",
            "        raise e.with_traceback(filtered_tb) from None\n",
            "    File \"/usr/local/lib/python3.8/dist-packages/keras/engine/input_spec.py\", line 295, in assert_input_compatibility\n",
            "        raise ValueError(\n",
            "\n",
            "    ValueError: Input 0 of layer \"sequential_2\" is incompatible with the layer: expected shape=(None, 3, 1), found shape=(None, 5, 1)\n",
            "\n",
            "\n",
            "--------------------------------------------------------------------------------\n",
            "1 fits failed with the following error:\n",
            "Traceback (most recent call last):\n",
            "  File \"/usr/local/lib/python3.8/dist-packages/sklearn/model_selection/_validation.py\", line 680, in _fit_and_score\n",
            "    estimator.fit(X_train, y_train, **fit_params)\n",
            "  File \"/usr/local/lib/python3.8/dist-packages/keras/wrappers/scikit_learn.py\", line 248, in fit\n",
            "    return super().fit(x, y, **kwargs)\n",
            "  File \"/usr/local/lib/python3.8/dist-packages/keras/wrappers/scikit_learn.py\", line 175, in fit\n",
            "    history = self.model.fit(x, y, **fit_args)\n",
            "  File \"/usr/local/lib/python3.8/dist-packages/keras/utils/traceback_utils.py\", line 70, in error_handler\n",
            "    raise e.with_traceback(filtered_tb) from None\n",
            "  File \"/tmp/__autograph_generated_filevd5txmnc.py\", line 15, in tf__train_function\n",
            "    retval_ = ag__.converted_call(ag__.ld(step_function), (ag__.ld(self), ag__.ld(iterator)), None, fscope)\n",
            "ValueError: in user code:\n",
            "\n",
            "    File \"/usr/local/lib/python3.8/dist-packages/keras/engine/training.py\", line 1249, in train_function  *\n",
            "        return step_function(self, iterator)\n",
            "    File \"/usr/local/lib/python3.8/dist-packages/keras/engine/training.py\", line 1233, in step_function  **\n",
            "        outputs = model.distribute_strategy.run(run_step, args=(data,))\n",
            "    File \"/usr/local/lib/python3.8/dist-packages/keras/engine/training.py\", line 1222, in run_step  **\n",
            "        outputs = model.train_step(data)\n",
            "    File \"/usr/local/lib/python3.8/dist-packages/keras/engine/training.py\", line 1023, in train_step\n",
            "        y_pred = self(x, training=True)\n",
            "    File \"/usr/local/lib/python3.8/dist-packages/keras/utils/traceback_utils.py\", line 70, in error_handler\n",
            "        raise e.with_traceback(filtered_tb) from None\n",
            "    File \"/usr/local/lib/python3.8/dist-packages/keras/engine/input_spec.py\", line 295, in assert_input_compatibility\n",
            "        raise ValueError(\n",
            "\n",
            "    ValueError: Input 0 of layer \"sequential_3\" is incompatible with the layer: expected shape=(None, 3, 1), found shape=(None, 5, 1)\n",
            "\n",
            "\n",
            "--------------------------------------------------------------------------------\n",
            "1 fits failed with the following error:\n",
            "Traceback (most recent call last):\n",
            "  File \"/usr/local/lib/python3.8/dist-packages/sklearn/model_selection/_validation.py\", line 680, in _fit_and_score\n",
            "    estimator.fit(X_train, y_train, **fit_params)\n",
            "  File \"/usr/local/lib/python3.8/dist-packages/keras/wrappers/scikit_learn.py\", line 248, in fit\n",
            "    return super().fit(x, y, **kwargs)\n",
            "  File \"/usr/local/lib/python3.8/dist-packages/keras/wrappers/scikit_learn.py\", line 175, in fit\n",
            "    history = self.model.fit(x, y, **fit_args)\n",
            "  File \"/usr/local/lib/python3.8/dist-packages/keras/utils/traceback_utils.py\", line 70, in error_handler\n",
            "    raise e.with_traceback(filtered_tb) from None\n",
            "  File \"/tmp/__autograph_generated_filevd5txmnc.py\", line 15, in tf__train_function\n",
            "    retval_ = ag__.converted_call(ag__.ld(step_function), (ag__.ld(self), ag__.ld(iterator)), None, fscope)\n",
            "ValueError: in user code:\n",
            "\n",
            "    File \"/usr/local/lib/python3.8/dist-packages/keras/engine/training.py\", line 1249, in train_function  *\n",
            "        return step_function(self, iterator)\n",
            "    File \"/usr/local/lib/python3.8/dist-packages/keras/engine/training.py\", line 1233, in step_function  **\n",
            "        outputs = model.distribute_strategy.run(run_step, args=(data,))\n",
            "    File \"/usr/local/lib/python3.8/dist-packages/keras/engine/training.py\", line 1222, in run_step  **\n",
            "        outputs = model.train_step(data)\n",
            "    File \"/usr/local/lib/python3.8/dist-packages/keras/engine/training.py\", line 1023, in train_step\n",
            "        y_pred = self(x, training=True)\n",
            "    File \"/usr/local/lib/python3.8/dist-packages/keras/utils/traceback_utils.py\", line 70, in error_handler\n",
            "        raise e.with_traceback(filtered_tb) from None\n",
            "    File \"/usr/local/lib/python3.8/dist-packages/keras/engine/input_spec.py\", line 295, in assert_input_compatibility\n",
            "        raise ValueError(\n",
            "\n",
            "    ValueError: Input 0 of layer \"sequential_4\" is incompatible with the layer: expected shape=(None, 3, 1), found shape=(None, 5, 1)\n",
            "\n",
            "\n",
            "--------------------------------------------------------------------------------\n",
            "1 fits failed with the following error:\n",
            "Traceback (most recent call last):\n",
            "  File \"/usr/local/lib/python3.8/dist-packages/sklearn/model_selection/_validation.py\", line 680, in _fit_and_score\n",
            "    estimator.fit(X_train, y_train, **fit_params)\n",
            "  File \"/usr/local/lib/python3.8/dist-packages/keras/wrappers/scikit_learn.py\", line 248, in fit\n",
            "    return super().fit(x, y, **kwargs)\n",
            "  File \"/usr/local/lib/python3.8/dist-packages/keras/wrappers/scikit_learn.py\", line 175, in fit\n",
            "    history = self.model.fit(x, y, **fit_args)\n",
            "  File \"/usr/local/lib/python3.8/dist-packages/keras/utils/traceback_utils.py\", line 70, in error_handler\n",
            "    raise e.with_traceback(filtered_tb) from None\n",
            "  File \"/tmp/__autograph_generated_filevd5txmnc.py\", line 15, in tf__train_function\n",
            "    retval_ = ag__.converted_call(ag__.ld(step_function), (ag__.ld(self), ag__.ld(iterator)), None, fscope)\n",
            "ValueError: in user code:\n",
            "\n",
            "    File \"/usr/local/lib/python3.8/dist-packages/keras/engine/training.py\", line 1249, in train_function  *\n",
            "        return step_function(self, iterator)\n",
            "    File \"/usr/local/lib/python3.8/dist-packages/keras/engine/training.py\", line 1233, in step_function  **\n",
            "        outputs = model.distribute_strategy.run(run_step, args=(data,))\n",
            "    File \"/usr/local/lib/python3.8/dist-packages/keras/engine/training.py\", line 1222, in run_step  **\n",
            "        outputs = model.train_step(data)\n",
            "    File \"/usr/local/lib/python3.8/dist-packages/keras/engine/training.py\", line 1023, in train_step\n",
            "        y_pred = self(x, training=True)\n",
            "    File \"/usr/local/lib/python3.8/dist-packages/keras/utils/traceback_utils.py\", line 70, in error_handler\n",
            "        raise e.with_traceback(filtered_tb) from None\n",
            "    File \"/usr/local/lib/python3.8/dist-packages/keras/engine/input_spec.py\", line 295, in assert_input_compatibility\n",
            "        raise ValueError(\n",
            "\n",
            "    ValueError: Input 0 of layer \"sequential_5\" is incompatible with the layer: expected shape=(None, 3, 1), found shape=(None, 5, 1)\n",
            "\n",
            "\n",
            "--------------------------------------------------------------------------------\n",
            "1 fits failed with the following error:\n",
            "Traceback (most recent call last):\n",
            "  File \"/usr/local/lib/python3.8/dist-packages/sklearn/model_selection/_validation.py\", line 680, in _fit_and_score\n",
            "    estimator.fit(X_train, y_train, **fit_params)\n",
            "  File \"/usr/local/lib/python3.8/dist-packages/keras/wrappers/scikit_learn.py\", line 248, in fit\n",
            "    return super().fit(x, y, **kwargs)\n",
            "  File \"/usr/local/lib/python3.8/dist-packages/keras/wrappers/scikit_learn.py\", line 175, in fit\n",
            "    history = self.model.fit(x, y, **fit_args)\n",
            "  File \"/usr/local/lib/python3.8/dist-packages/keras/utils/traceback_utils.py\", line 70, in error_handler\n",
            "    raise e.with_traceback(filtered_tb) from None\n",
            "  File \"/tmp/__autograph_generated_filevd5txmnc.py\", line 15, in tf__train_function\n",
            "    retval_ = ag__.converted_call(ag__.ld(step_function), (ag__.ld(self), ag__.ld(iterator)), None, fscope)\n",
            "ValueError: in user code:\n",
            "\n",
            "    File \"/usr/local/lib/python3.8/dist-packages/keras/engine/training.py\", line 1249, in train_function  *\n",
            "        return step_function(self, iterator)\n",
            "    File \"/usr/local/lib/python3.8/dist-packages/keras/engine/training.py\", line 1233, in step_function  **\n",
            "        outputs = model.distribute_strategy.run(run_step, args=(data,))\n",
            "    File \"/usr/local/lib/python3.8/dist-packages/keras/engine/training.py\", line 1222, in run_step  **\n",
            "        outputs = model.train_step(data)\n",
            "    File \"/usr/local/lib/python3.8/dist-packages/keras/engine/training.py\", line 1023, in train_step\n",
            "        y_pred = self(x, training=True)\n",
            "    File \"/usr/local/lib/python3.8/dist-packages/keras/utils/traceback_utils.py\", line 70, in error_handler\n",
            "        raise e.with_traceback(filtered_tb) from None\n",
            "    File \"/usr/local/lib/python3.8/dist-packages/keras/engine/input_spec.py\", line 295, in assert_input_compatibility\n",
            "        raise ValueError(\n",
            "\n",
            "    ValueError: Input 0 of layer \"sequential_11\" is incompatible with the layer: expected shape=(None, 7, 1), found shape=(None, 5, 1)\n",
            "\n",
            "\n",
            "--------------------------------------------------------------------------------\n",
            "1 fits failed with the following error:\n",
            "Traceback (most recent call last):\n",
            "  File \"/usr/local/lib/python3.8/dist-packages/sklearn/model_selection/_validation.py\", line 680, in _fit_and_score\n",
            "    estimator.fit(X_train, y_train, **fit_params)\n",
            "  File \"/usr/local/lib/python3.8/dist-packages/keras/wrappers/scikit_learn.py\", line 248, in fit\n",
            "    return super().fit(x, y, **kwargs)\n",
            "  File \"/usr/local/lib/python3.8/dist-packages/keras/wrappers/scikit_learn.py\", line 175, in fit\n",
            "    history = self.model.fit(x, y, **fit_args)\n",
            "  File \"/usr/local/lib/python3.8/dist-packages/keras/utils/traceback_utils.py\", line 70, in error_handler\n",
            "    raise e.with_traceback(filtered_tb) from None\n",
            "  File \"/tmp/__autograph_generated_filevd5txmnc.py\", line 15, in tf__train_function\n",
            "    retval_ = ag__.converted_call(ag__.ld(step_function), (ag__.ld(self), ag__.ld(iterator)), None, fscope)\n",
            "ValueError: in user code:\n",
            "\n",
            "    File \"/usr/local/lib/python3.8/dist-packages/keras/engine/training.py\", line 1249, in train_function  *\n",
            "        return step_function(self, iterator)\n",
            "    File \"/usr/local/lib/python3.8/dist-packages/keras/engine/training.py\", line 1233, in step_function  **\n",
            "        outputs = model.distribute_strategy.run(run_step, args=(data,))\n",
            "    File \"/usr/local/lib/python3.8/dist-packages/keras/engine/training.py\", line 1222, in run_step  **\n",
            "        outputs = model.train_step(data)\n",
            "    File \"/usr/local/lib/python3.8/dist-packages/keras/engine/training.py\", line 1023, in train_step\n",
            "        y_pred = self(x, training=True)\n",
            "    File \"/usr/local/lib/python3.8/dist-packages/keras/utils/traceback_utils.py\", line 70, in error_handler\n",
            "        raise e.with_traceback(filtered_tb) from None\n",
            "    File \"/usr/local/lib/python3.8/dist-packages/keras/engine/input_spec.py\", line 295, in assert_input_compatibility\n",
            "        raise ValueError(\n",
            "\n",
            "    ValueError: Input 0 of layer \"sequential_12\" is incompatible with the layer: expected shape=(None, 7, 1), found shape=(None, 5, 1)\n",
            "\n",
            "\n",
            "--------------------------------------------------------------------------------\n",
            "1 fits failed with the following error:\n",
            "Traceback (most recent call last):\n",
            "  File \"/usr/local/lib/python3.8/dist-packages/sklearn/model_selection/_validation.py\", line 680, in _fit_and_score\n",
            "    estimator.fit(X_train, y_train, **fit_params)\n",
            "  File \"/usr/local/lib/python3.8/dist-packages/keras/wrappers/scikit_learn.py\", line 248, in fit\n",
            "    return super().fit(x, y, **kwargs)\n",
            "  File \"/usr/local/lib/python3.8/dist-packages/keras/wrappers/scikit_learn.py\", line 175, in fit\n",
            "    history = self.model.fit(x, y, **fit_args)\n",
            "  File \"/usr/local/lib/python3.8/dist-packages/keras/utils/traceback_utils.py\", line 70, in error_handler\n",
            "    raise e.with_traceback(filtered_tb) from None\n",
            "  File \"/tmp/__autograph_generated_filevd5txmnc.py\", line 15, in tf__train_function\n",
            "    retval_ = ag__.converted_call(ag__.ld(step_function), (ag__.ld(self), ag__.ld(iterator)), None, fscope)\n",
            "ValueError: in user code:\n",
            "\n",
            "    File \"/usr/local/lib/python3.8/dist-packages/keras/engine/training.py\", line 1249, in train_function  *\n",
            "        return step_function(self, iterator)\n",
            "    File \"/usr/local/lib/python3.8/dist-packages/keras/engine/training.py\", line 1233, in step_function  **\n",
            "        outputs = model.distribute_strategy.run(run_step, args=(data,))\n",
            "    File \"/usr/local/lib/python3.8/dist-packages/keras/engine/training.py\", line 1222, in run_step  **\n",
            "        outputs = model.train_step(data)\n",
            "    File \"/usr/local/lib/python3.8/dist-packages/keras/engine/training.py\", line 1023, in train_step\n",
            "        y_pred = self(x, training=True)\n",
            "    File \"/usr/local/lib/python3.8/dist-packages/keras/utils/traceback_utils.py\", line 70, in error_handler\n",
            "        raise e.with_traceback(filtered_tb) from None\n",
            "    File \"/usr/local/lib/python3.8/dist-packages/keras/engine/input_spec.py\", line 295, in assert_input_compatibility\n",
            "        raise ValueError(\n",
            "\n",
            "    ValueError: Input 0 of layer \"sequential_13\" is incompatible with the layer: expected shape=(None, 7, 1), found shape=(None, 5, 1)\n",
            "\n",
            "\n",
            "--------------------------------------------------------------------------------\n",
            "1 fits failed with the following error:\n",
            "Traceback (most recent call last):\n",
            "  File \"/usr/local/lib/python3.8/dist-packages/sklearn/model_selection/_validation.py\", line 680, in _fit_and_score\n",
            "    estimator.fit(X_train, y_train, **fit_params)\n",
            "  File \"/usr/local/lib/python3.8/dist-packages/keras/wrappers/scikit_learn.py\", line 248, in fit\n",
            "    return super().fit(x, y, **kwargs)\n",
            "  File \"/usr/local/lib/python3.8/dist-packages/keras/wrappers/scikit_learn.py\", line 175, in fit\n",
            "    history = self.model.fit(x, y, **fit_args)\n",
            "  File \"/usr/local/lib/python3.8/dist-packages/keras/utils/traceback_utils.py\", line 70, in error_handler\n",
            "    raise e.with_traceback(filtered_tb) from None\n",
            "  File \"/tmp/__autograph_generated_filevd5txmnc.py\", line 15, in tf__train_function\n",
            "    retval_ = ag__.converted_call(ag__.ld(step_function), (ag__.ld(self), ag__.ld(iterator)), None, fscope)\n",
            "ValueError: in user code:\n",
            "\n",
            "    File \"/usr/local/lib/python3.8/dist-packages/keras/engine/training.py\", line 1249, in train_function  *\n",
            "        return step_function(self, iterator)\n",
            "    File \"/usr/local/lib/python3.8/dist-packages/keras/engine/training.py\", line 1233, in step_function  **\n",
            "        outputs = model.distribute_strategy.run(run_step, args=(data,))\n",
            "    File \"/usr/local/lib/python3.8/dist-packages/keras/engine/training.py\", line 1222, in run_step  **\n",
            "        outputs = model.train_step(data)\n",
            "    File \"/usr/local/lib/python3.8/dist-packages/keras/engine/training.py\", line 1023, in train_step\n",
            "        y_pred = self(x, training=True)\n",
            "    File \"/usr/local/lib/python3.8/dist-packages/keras/utils/traceback_utils.py\", line 70, in error_handler\n",
            "        raise e.with_traceback(filtered_tb) from None\n",
            "    File \"/usr/local/lib/python3.8/dist-packages/keras/engine/input_spec.py\", line 295, in assert_input_compatibility\n",
            "        raise ValueError(\n",
            "\n",
            "    ValueError: Input 0 of layer \"sequential_14\" is incompatible with the layer: expected shape=(None, 7, 1), found shape=(None, 5, 1)\n",
            "\n",
            "\n",
            "--------------------------------------------------------------------------------\n",
            "1 fits failed with the following error:\n",
            "Traceback (most recent call last):\n",
            "  File \"/usr/local/lib/python3.8/dist-packages/sklearn/model_selection/_validation.py\", line 680, in _fit_and_score\n",
            "    estimator.fit(X_train, y_train, **fit_params)\n",
            "  File \"/usr/local/lib/python3.8/dist-packages/keras/wrappers/scikit_learn.py\", line 248, in fit\n",
            "    return super().fit(x, y, **kwargs)\n",
            "  File \"/usr/local/lib/python3.8/dist-packages/keras/wrappers/scikit_learn.py\", line 175, in fit\n",
            "    history = self.model.fit(x, y, **fit_args)\n",
            "  File \"/usr/local/lib/python3.8/dist-packages/keras/utils/traceback_utils.py\", line 70, in error_handler\n",
            "    raise e.with_traceback(filtered_tb) from None\n",
            "  File \"/tmp/__autograph_generated_filevd5txmnc.py\", line 15, in tf__train_function\n",
            "    retval_ = ag__.converted_call(ag__.ld(step_function), (ag__.ld(self), ag__.ld(iterator)), None, fscope)\n",
            "ValueError: in user code:\n",
            "\n",
            "    File \"/usr/local/lib/python3.8/dist-packages/keras/engine/training.py\", line 1249, in train_function  *\n",
            "        return step_function(self, iterator)\n",
            "    File \"/usr/local/lib/python3.8/dist-packages/keras/engine/training.py\", line 1233, in step_function  **\n",
            "        outputs = model.distribute_strategy.run(run_step, args=(data,))\n",
            "    File \"/usr/local/lib/python3.8/dist-packages/keras/engine/training.py\", line 1222, in run_step  **\n",
            "        outputs = model.train_step(data)\n",
            "    File \"/usr/local/lib/python3.8/dist-packages/keras/engine/training.py\", line 1023, in train_step\n",
            "        y_pred = self(x, training=True)\n",
            "    File \"/usr/local/lib/python3.8/dist-packages/keras/utils/traceback_utils.py\", line 70, in error_handler\n",
            "        raise e.with_traceback(filtered_tb) from None\n",
            "    File \"/usr/local/lib/python3.8/dist-packages/keras/engine/input_spec.py\", line 295, in assert_input_compatibility\n",
            "        raise ValueError(\n",
            "\n",
            "    ValueError: Input 0 of layer \"sequential_15\" is incompatible with the layer: expected shape=(None, 7, 1), found shape=(None, 5, 1)\n",
            "\n",
            "\n",
            "--------------------------------------------------------------------------------\n",
            "1 fits failed with the following error:\n",
            "Traceback (most recent call last):\n",
            "  File \"/usr/local/lib/python3.8/dist-packages/sklearn/model_selection/_validation.py\", line 680, in _fit_and_score\n",
            "    estimator.fit(X_train, y_train, **fit_params)\n",
            "  File \"/usr/local/lib/python3.8/dist-packages/keras/wrappers/scikit_learn.py\", line 248, in fit\n",
            "    return super().fit(x, y, **kwargs)\n",
            "  File \"/usr/local/lib/python3.8/dist-packages/keras/wrappers/scikit_learn.py\", line 175, in fit\n",
            "    history = self.model.fit(x, y, **fit_args)\n",
            "  File \"/usr/local/lib/python3.8/dist-packages/keras/utils/traceback_utils.py\", line 70, in error_handler\n",
            "    raise e.with_traceback(filtered_tb) from None\n",
            "  File \"/tmp/__autograph_generated_filevd5txmnc.py\", line 15, in tf__train_function\n",
            "    retval_ = ag__.converted_call(ag__.ld(step_function), (ag__.ld(self), ag__.ld(iterator)), None, fscope)\n",
            "ValueError: in user code:\n",
            "\n",
            "    File \"/usr/local/lib/python3.8/dist-packages/keras/engine/training.py\", line 1249, in train_function  *\n",
            "        return step_function(self, iterator)\n",
            "    File \"/usr/local/lib/python3.8/dist-packages/keras/engine/training.py\", line 1233, in step_function  **\n",
            "        outputs = model.distribute_strategy.run(run_step, args=(data,))\n",
            "    File \"/usr/local/lib/python3.8/dist-packages/keras/engine/training.py\", line 1222, in run_step  **\n",
            "        outputs = model.train_step(data)\n",
            "    File \"/usr/local/lib/python3.8/dist-packages/keras/engine/training.py\", line 1023, in train_step\n",
            "        y_pred = self(x, training=True)\n",
            "    File \"/usr/local/lib/python3.8/dist-packages/keras/utils/traceback_utils.py\", line 70, in error_handler\n",
            "        raise e.with_traceback(filtered_tb) from None\n",
            "    File \"/usr/local/lib/python3.8/dist-packages/keras/engine/input_spec.py\", line 295, in assert_input_compatibility\n",
            "        raise ValueError(\n",
            "\n",
            "    ValueError: Input 0 of layer \"sequential_16\" is incompatible with the layer: expected shape=(None, 10, 1), found shape=(None, 5, 1)\n",
            "\n",
            "\n",
            "--------------------------------------------------------------------------------\n",
            "1 fits failed with the following error:\n",
            "Traceback (most recent call last):\n",
            "  File \"/usr/local/lib/python3.8/dist-packages/sklearn/model_selection/_validation.py\", line 680, in _fit_and_score\n",
            "    estimator.fit(X_train, y_train, **fit_params)\n",
            "  File \"/usr/local/lib/python3.8/dist-packages/keras/wrappers/scikit_learn.py\", line 248, in fit\n",
            "    return super().fit(x, y, **kwargs)\n",
            "  File \"/usr/local/lib/python3.8/dist-packages/keras/wrappers/scikit_learn.py\", line 175, in fit\n",
            "    history = self.model.fit(x, y, **fit_args)\n",
            "  File \"/usr/local/lib/python3.8/dist-packages/keras/utils/traceback_utils.py\", line 70, in error_handler\n",
            "    raise e.with_traceback(filtered_tb) from None\n",
            "  File \"/tmp/__autograph_generated_filevd5txmnc.py\", line 15, in tf__train_function\n",
            "    retval_ = ag__.converted_call(ag__.ld(step_function), (ag__.ld(self), ag__.ld(iterator)), None, fscope)\n",
            "ValueError: in user code:\n",
            "\n",
            "    File \"/usr/local/lib/python3.8/dist-packages/keras/engine/training.py\", line 1249, in train_function  *\n",
            "        return step_function(self, iterator)\n",
            "    File \"/usr/local/lib/python3.8/dist-packages/keras/engine/training.py\", line 1233, in step_function  **\n",
            "        outputs = model.distribute_strategy.run(run_step, args=(data,))\n",
            "    File \"/usr/local/lib/python3.8/dist-packages/keras/engine/training.py\", line 1222, in run_step  **\n",
            "        outputs = model.train_step(data)\n",
            "    File \"/usr/local/lib/python3.8/dist-packages/keras/engine/training.py\", line 1023, in train_step\n",
            "        y_pred = self(x, training=True)\n",
            "    File \"/usr/local/lib/python3.8/dist-packages/keras/utils/traceback_utils.py\", line 70, in error_handler\n",
            "        raise e.with_traceback(filtered_tb) from None\n",
            "    File \"/usr/local/lib/python3.8/dist-packages/keras/engine/input_spec.py\", line 295, in assert_input_compatibility\n",
            "        raise ValueError(\n",
            "\n",
            "    ValueError: Input 0 of layer \"sequential_17\" is incompatible with the layer: expected shape=(None, 10, 1), found shape=(None, 5, 1)\n",
            "\n",
            "\n",
            "--------------------------------------------------------------------------------\n",
            "1 fits failed with the following error:\n",
            "Traceback (most recent call last):\n",
            "  File \"/usr/local/lib/python3.8/dist-packages/sklearn/model_selection/_validation.py\", line 680, in _fit_and_score\n",
            "    estimator.fit(X_train, y_train, **fit_params)\n",
            "  File \"/usr/local/lib/python3.8/dist-packages/keras/wrappers/scikit_learn.py\", line 248, in fit\n",
            "    return super().fit(x, y, **kwargs)\n",
            "  File \"/usr/local/lib/python3.8/dist-packages/keras/wrappers/scikit_learn.py\", line 175, in fit\n",
            "    history = self.model.fit(x, y, **fit_args)\n",
            "  File \"/usr/local/lib/python3.8/dist-packages/keras/utils/traceback_utils.py\", line 70, in error_handler\n",
            "    raise e.with_traceback(filtered_tb) from None\n",
            "  File \"/tmp/__autograph_generated_filevd5txmnc.py\", line 15, in tf__train_function\n",
            "    retval_ = ag__.converted_call(ag__.ld(step_function), (ag__.ld(self), ag__.ld(iterator)), None, fscope)\n",
            "ValueError: in user code:\n",
            "\n",
            "    File \"/usr/local/lib/python3.8/dist-packages/keras/engine/training.py\", line 1249, in train_function  *\n",
            "        return step_function(self, iterator)\n",
            "    File \"/usr/local/lib/python3.8/dist-packages/keras/engine/training.py\", line 1233, in step_function  **\n",
            "        outputs = model.distribute_strategy.run(run_step, args=(data,))\n",
            "    File \"/usr/local/lib/python3.8/dist-packages/keras/engine/training.py\", line 1222, in run_step  **\n",
            "        outputs = model.train_step(data)\n",
            "    File \"/usr/local/lib/python3.8/dist-packages/keras/engine/training.py\", line 1023, in train_step\n",
            "        y_pred = self(x, training=True)\n",
            "    File \"/usr/local/lib/python3.8/dist-packages/keras/utils/traceback_utils.py\", line 70, in error_handler\n",
            "        raise e.with_traceback(filtered_tb) from None\n",
            "    File \"/usr/local/lib/python3.8/dist-packages/keras/engine/input_spec.py\", line 295, in assert_input_compatibility\n",
            "        raise ValueError(\n",
            "\n",
            "    ValueError: Input 0 of layer \"sequential_18\" is incompatible with the layer: expected shape=(None, 10, 1), found shape=(None, 5, 1)\n",
            "\n",
            "\n",
            "--------------------------------------------------------------------------------\n",
            "1 fits failed with the following error:\n",
            "Traceback (most recent call last):\n",
            "  File \"/usr/local/lib/python3.8/dist-packages/sklearn/model_selection/_validation.py\", line 680, in _fit_and_score\n",
            "    estimator.fit(X_train, y_train, **fit_params)\n",
            "  File \"/usr/local/lib/python3.8/dist-packages/keras/wrappers/scikit_learn.py\", line 248, in fit\n",
            "    return super().fit(x, y, **kwargs)\n",
            "  File \"/usr/local/lib/python3.8/dist-packages/keras/wrappers/scikit_learn.py\", line 175, in fit\n",
            "    history = self.model.fit(x, y, **fit_args)\n",
            "  File \"/usr/local/lib/python3.8/dist-packages/keras/utils/traceback_utils.py\", line 70, in error_handler\n",
            "    raise e.with_traceback(filtered_tb) from None\n",
            "  File \"/tmp/__autograph_generated_filevd5txmnc.py\", line 15, in tf__train_function\n",
            "    retval_ = ag__.converted_call(ag__.ld(step_function), (ag__.ld(self), ag__.ld(iterator)), None, fscope)\n",
            "ValueError: in user code:\n",
            "\n",
            "    File \"/usr/local/lib/python3.8/dist-packages/keras/engine/training.py\", line 1249, in train_function  *\n",
            "        return step_function(self, iterator)\n",
            "    File \"/usr/local/lib/python3.8/dist-packages/keras/engine/training.py\", line 1233, in step_function  **\n",
            "        outputs = model.distribute_strategy.run(run_step, args=(data,))\n",
            "    File \"/usr/local/lib/python3.8/dist-packages/keras/engine/training.py\", line 1222, in run_step  **\n",
            "        outputs = model.train_step(data)\n",
            "    File \"/usr/local/lib/python3.8/dist-packages/keras/engine/training.py\", line 1023, in train_step\n",
            "        y_pred = self(x, training=True)\n",
            "    File \"/usr/local/lib/python3.8/dist-packages/keras/utils/traceback_utils.py\", line 70, in error_handler\n",
            "        raise e.with_traceback(filtered_tb) from None\n",
            "    File \"/usr/local/lib/python3.8/dist-packages/keras/engine/input_spec.py\", line 295, in assert_input_compatibility\n",
            "        raise ValueError(\n",
            "\n",
            "    ValueError: Input 0 of layer \"sequential_19\" is incompatible with the layer: expected shape=(None, 10, 1), found shape=(None, 5, 1)\n",
            "\n",
            "\n",
            "--------------------------------------------------------------------------------\n",
            "1 fits failed with the following error:\n",
            "Traceback (most recent call last):\n",
            "  File \"/usr/local/lib/python3.8/dist-packages/sklearn/model_selection/_validation.py\", line 680, in _fit_and_score\n",
            "    estimator.fit(X_train, y_train, **fit_params)\n",
            "  File \"/usr/local/lib/python3.8/dist-packages/keras/wrappers/scikit_learn.py\", line 248, in fit\n",
            "    return super().fit(x, y, **kwargs)\n",
            "  File \"/usr/local/lib/python3.8/dist-packages/keras/wrappers/scikit_learn.py\", line 175, in fit\n",
            "    history = self.model.fit(x, y, **fit_args)\n",
            "  File \"/usr/local/lib/python3.8/dist-packages/keras/utils/traceback_utils.py\", line 70, in error_handler\n",
            "    raise e.with_traceback(filtered_tb) from None\n",
            "  File \"/tmp/__autograph_generated_filevd5txmnc.py\", line 15, in tf__train_function\n",
            "    retval_ = ag__.converted_call(ag__.ld(step_function), (ag__.ld(self), ag__.ld(iterator)), None, fscope)\n",
            "ValueError: in user code:\n",
            "\n",
            "    File \"/usr/local/lib/python3.8/dist-packages/keras/engine/training.py\", line 1249, in train_function  *\n",
            "        return step_function(self, iterator)\n",
            "    File \"/usr/local/lib/python3.8/dist-packages/keras/engine/training.py\", line 1233, in step_function  **\n",
            "        outputs = model.distribute_strategy.run(run_step, args=(data,))\n",
            "    File \"/usr/local/lib/python3.8/dist-packages/keras/engine/training.py\", line 1222, in run_step  **\n",
            "        outputs = model.train_step(data)\n",
            "    File \"/usr/local/lib/python3.8/dist-packages/keras/engine/training.py\", line 1023, in train_step\n",
            "        y_pred = self(x, training=True)\n",
            "    File \"/usr/local/lib/python3.8/dist-packages/keras/utils/traceback_utils.py\", line 70, in error_handler\n",
            "        raise e.with_traceback(filtered_tb) from None\n",
            "    File \"/usr/local/lib/python3.8/dist-packages/keras/engine/input_spec.py\", line 295, in assert_input_compatibility\n",
            "        raise ValueError(\n",
            "\n",
            "    ValueError: Input 0 of layer \"sequential_20\" is incompatible with the layer: expected shape=(None, 10, 1), found shape=(None, 5, 1)\n",
            "\n",
            "\n",
            "  warnings.warn(some_fits_failed_message, FitFailedWarning)\n",
            "/usr/local/lib/python3.8/dist-packages/sklearn/model_selection/_search.py:969: UserWarning: One or more of the test scores are non-finite: [       nan 0.48624755        nan        nan]\n",
            "  warnings.warn(\n"
          ]
        },
        {
          "output_type": "stream",
          "name": "stdout",
          "text": [
            "Best input size: 5\n",
            "Best mean test score: 0.4862475454807281\n"
          ]
        }
      ]
    }
  ]
}